Workbook

Sheet Dashboard
A1: VINLAND
A2: Development dashboard · one page for scope, time, and cost
A4: Working title | B4: =Assumptions!B5 -> Vinland | E4: PHASE COST
A5: Production start | B5: =Assumptions!B8 -> 46328 | E5: Phase | F5: Weeks | G5: Labor | H5: Share
A6: Total weeks | B6: =Assumptions!B22 -> 52 | E6: =TeamBudget!A15 -> Preproduction | F6: =TeamBudget!B15 -> 8 | G6: =TeamBudget!J15 -> 30600 | H6: =IF(TeamBudget!$B$35=0,0,G6/TeamBudget!$B$35) -> 0.094707521
A7: Target ship | B7: =Assumptions!C22 -> 46691 | E7: =TeamBudget!A16 -> Vertical slice | F7: =TeamBudget!B16 -> 10 | G7: =TeamBudget!J16 -> 63600 | H7: =IF(TeamBudget!$B$35=0,0,G7/TeamBudget!$B$35) -> 0.19684308
A8: Labor cost | B8: =TeamBudget!B35 -> 323100 | E8: =TeamBudget!A17 -> Production | F8: =TeamBudget!B17 -> 18 | G8: =TeamBudget!J17 -> 118800 | H8: =IF(TeamBudget!$B$35=0,0,G8/TeamBudget!$B$35) -> 0.36768802
A9: Fully loaded cost | B9: =TeamBudget!B36 -> 460504.8 | E9: =TeamBudget!A18 -> Alpha | F9: =TeamBudget!B18 -> 6 | G9: =TeamBudget!J18 -> 46400 | H9: =IF(TeamBudget!$B$35=0,0,G9/TeamBudget!$B$35) -> 0.14360879
A10: Backlog items | B10: =COUNTA(Backlog!A5:A80) -> 65 | E10: =TeamBudget!A19 -> Beta | F10: =TeamBudget!B19 -> 6 | G10: =TeamBudget!J19 -> 39100 | H10: =IF(TeamBudget!$B$35=0,0,G10/TeamBudget!$B$35) -> 0.12101517
A11: Must-ship items | B11: =COUNTIF(Backlog!E5:E80,"Must") -> 54 | E11: =TeamBudget!A20 -> Polish and ship | F11: =TeamBudget!B20 -> 4 | G11: =TeamBudget!J20 -> 24600 | H11: =IF(TeamBudget!$B$35=0,0,G11/TeamBudget!$B$35) -> 0.076137419
A12: Break-even units | B12: =Breakeven!B15 -> 44085 | E12: Total | F12: =SUM(F6:F11) -> 52 | G12: =SUM(G6:G11) -> 323100 | H12: =SUM(H6:H11) -> 1
A13: WHAT THE GAME IS
A14: Oregon Trail structure on the Karlsefni voyage. Leave Greenland in a knarr with a hold that is already full. Keep latitude with a star ring and a sun board. Fish, hunt, forage, and build with the same gamepad grammar. Winter a camp. Trade milk and red cloth until fear caps. Send timber home. Bring a second ship back. A qualified win is the saga ending: leave rich. A full win is a manned camp that has sent two cargoes and received one relief ship.
A18: FIVE VERBS · NOTHING IS A SIDE ACTIVITY
A19: Verb | B19: Mini-game | E19: Pays the hold
A20: Navigate | B20: Ring and sun board | E20: Refunds drift, saves food
A21: Fish | B21: Line and net | E21: Meals, then a food unit if dried
A22: Hunt | B22: One-shot stalk | E22: Meat, hides, a possible fear tick
A23: Forage | B23: Measured take | E23: Calories now, or a patch next season
A24: Build | B24: Joint and lift | E24: Byre, rack, slipway, the return itself
A26: SCOPE GATE
A27: Cut order if the vertical slice slips: Hóp second site, sealing, the Thorhall split, then the third summer. Never cut the star ring, the hold, the byre, the fear clock, or the return cargo. Those five are the game.
A43: HEALTH CHECKS · READ AT EVERY GATE
A44: Check | B44: Value | C44: Target | E44: Status | F44: Source
A45: Backlog load, all owners | B45: =Backlog!E97 -> 0.39661017 | C45: 60% or less | E45: =IF(B45<=0.6,"OK",IF(B45<=0.8,"Tight","Over")) -> OK | F45: Backlog capacity check
A46: Most loaded owner | B46: =INDEX(Backlog!$A$91:$A$96,MATCH(MAX(Backlog!$E$91:$E$96),Backlog!$E$91:$E$96,0))&" · "&TEXT(MAX(Backlog!$E$91:$E$96),"0%") -> Design · 83% | C46: 80% or less | E46: =IF(MAX(Backlog!$E$91:$E$96)<=0.6,"OK",IF(MAX(Backlog!$E$91:$E$96)<=0.8,"Tight","Over")) -> Over | F46: Backlog capacity check
A47: Spare hold at departure (units) | B47: =HoldCheck!D23 -> 0 | C47: 0 to 1: full but legal | E47: =IF(B47<0,"Over",IF(B47<1,"OK","Tight")) -> OK | F47: HoldCheck
A48: Timber units that fit going home | B48: =HoldCheck!D32 -> 17 | C48: =">= "&Assumptions!B49 -> >= 4 | E48: =IF(B48>=Assumptions!B49,"OK","Over") -> OK | F48: HoldCheck
A49: Planned crossing days | B49: =HoldCheck!B10 -> 13 | C49: Info | E49: ="Info" -> Info | F49: HoldCheck
A50: Net per unit sold | B50: =Breakeven!B10 -> 10.445974 | C50: Info | E50: ="Info" -> Info | F50: Breakeven
A51: Units to recover cash outlay | B51: =Breakeven!B17 -> 9443 | C51: Info | E51: ="Info" -> Info | F51: Breakeven
A52: Highest risk score | B52: =MAX(Risks!E5:E20) -> 16 | C52: Below 15 | E52: =IF(B52>=15,"Act",IF(B52>=12,"Tight","OK")) -> Act | F52: Risks
A53: Top risk | B53: =INDEX(Risks!B5:B20,MATCH(MAX(Risks!E5:E20),Risks!E5:E20,0)) -> Store page goes up too late to build wishlists | C53: Owner acting on it | E53: ="Info" -> Info | F53: Risks
A54: Risks scored 12+ not closed | B54: =COUNTIFS(Risks!E5:E20,">=12",Risks!J5:J20,"<>Closed") -> 9 | C54: 0 by Beta | E54: =IF(B54=0,"OK","Tight") -> Tight | F54: Risks
A55: Backlog items done | B55: =COUNTIF(Backlog!I5:I80,"Done")&" of "&COUNTA(Backlog!A5:A80) -> 7 of 65 | C55: Tracks the phase | E55: ="Info" -> Info | F55: Backlog status
A56: Must-ship days done | B56: =Backlog!G86 -> 0.16993464 | C56: 100% at G3 | E56: ="Info" -> Info | F56: Backlog status
A57: Gates passed | B57: =COUNTIF(Milestones!F5:F10,"Passed")&" of 6" -> 2 of 6 | C57: One per phase | E57: ="Info" -> Info | F57: Milestones status

Sheet Assumptions
A1: VINLAND
A2: Assumptions · edit the yellow cells; every other sheet recalculates from here
A4: PROJECT
A5: Working title | B5: Vinland
A6: Studio / lead | B6: Independent · Nick Doney Sr. (nickdoneysr)
A7: Plan date | B7: 46304 | C7: Revised 16 Oct 2026
A8: Production start | B8: 46328 | C8: Every date in the workbook flows from this cell
A9: Target platform | B9: PC, gamepad-first | C9: Steam Deck Verified is the stretch target
A10: Engine assumption | B10: Godot 4.3, 2D painted | C10: Decided 17 Oct 2026: one project exports PC (Steam) and HTML5 (itch.io)
A11: Build scope | B11: Single-player, 6 to 8 hours | C11: One run is three summers, roughly three evenings
A12: Currency | B12: USD
A14: PHASE LENGTHS (WEEKS)
A15: Phase | B15: Weeks | C15: Notes
A16: Preproduction | B16: 8 | C16: Pillar lock, paper prototype of the ring and the hold, vertical-slice scope
A17: Vertical slice | B17: 10 | C17: One sea leg, star ring, line fishing, one camp day, one joint
A18: Production | B18: 18 | C18: All legs, all five verbs, settlement year, trade, return voyage
A19: Alpha | B19: 6 | C19: Feature complete, economy pass, first full three-summer run
A20: Beta | B20: 6 | C20: Difficulty, haptics, accessibility, content lock
A21: Polish and ship | B21: 4 | C21: Store page, trailer, day-one patch buffer
A22: Total weeks · target ship | B22: =SUM(B16:B21) -> 52 | C22: =B8+B22*7-1 -> 46691
A24: RATES AND OVERHEAD
A25: Item | B25: Value | C25: Unit / note
A26: Design week rate | B26: 1800 | C26: USD per person-week, blended
A27: Engineering week rate | B27: 2200 | C27: USD per person-week, blended
A28: Art week rate | B28: 1700 | C28: USD per person-week, blended
A29: Audio week rate | B29: 1600 | C29: USD per person-week, contractor
A30: QA week rate | B30: 1200 | C30: USD per person-week
A31: Production week rate | B31: 1900 | C31: USD per person-week
A32: Overhead on labor | B32: 0.15 | C32: Tools, engine seats, cloud builds
A33: Contingency | B33: 0.12 | C33: Applied after overhead
A34: Outsource art budget | B34: 18000 | C34: USD, ships, UI frames, sky plates
A35: Music and foley budget | B35: 12000 | C35: USD, beyond staff audio weeks
A36: Store, trailer, legal | B36: 4000 | C36: USD
A37: Playtest honoraria | B37: 2500 | C37: USD
A39: ECONOMY TUNING KNOBS (DESIGN INPUTS)
A40: Knob | B40: Value | C40: Used by
A41: Knarr cargo units | B41: 24 | C41: Hull model
A42: Party size, default | B42: 24 | C42: Starting load
A43: Food unit feeds (people x days) | B43: 168 | C43: 12 people x 14 days
A44: Drink unit covers (people x days) | B44: 120 | C44: 12 people x 10 days
...

Sheet Pillars
A1: VINLAND
A2: Pillars, fantasy, clocks, and the win
A4: ID | B4: Pillar | C4: Player promise | D4: Fails if | E4: Design owner
A5: P1 | B5: The hold is the game | C5: Every fun verb spends cargo, a watch, or a body. | D5: A mini-game pays out points that do not fit in the hull. | E5: Design
A6: P2 | B6: Latitude, not a chart | C6: Clear nights buy a shorter leg. Fog is missing information, not a blank screen. | D6: The player can win by confirming a menu. | E6: Design
A7: P3 | B7: One controller grammar | C7: Left stick gross, right stick fine, triggers force, B is the safe drop. | D7: A verb invents its own buttons. | E7: Design
A8: P4 | B8: Season is a clock | C8: Leave after the ice. October at sea is a loss. Winter is survival, not travel. | D8: The player can sail whenever. | E8: Design
A9: P5 | B9: The colony is the point | C9: Karlsefni, not Leif. Livestock, a birth, a byre, a market. | D9: The game ends at landfall. | E9: Design
A10: P6 | B10: Trade until it doesn't | C10: Milk and red cloth buy peace. A weapon sale or a killing caps fear. | D10: Natives are a faction toggle. | E10: Design
A11: P7 | B11: The return is the win | C11: Timber home funds the next hull. Two cargoes and one relief ship is the full win. | D11: Score is distance sailed. | E11: Design
A12: P8 | B12: Qualified saga ending | C12: Load everyone and leave rich is allowed, and scored below a living camp. | D12: The game scolds the historical ending. | E12: Design
A14: THREE CLOCKS
A15: Clock | B15: Ticks when | C15: Player lever | D15: Loss | E15: Notes
A16: Season | B16: Each watch and each camp day | C16: Pace: crack on, easy, heave to | D16: Still at sea in October | E16: Late May departure, September last open water
A17: Ship | B17: Weather checks, sail strain, sprung strake | C17: Heave to versus run | D17: Hull lost with no camp behind it | E17: A knarr does not fight a storm
A18: Colony | B18: Rations, hay, fear, relief | C18: Byre, rack, market, who sails home | D18: Winter starve, or fear capped and both hulls gone | E18: A camp that only feeds itself dies when the ship does not return
A20: OUTFITS
A21: Outfit | B21: Silver | C21: Strength | D21: Weakness | E21: Starting feel
A22: Farm household | B22: Low | C22: Livestock, cheese, fodder skill | D22: Small cargo, few fighters | E22: The byre is easier, the hold is tighter
A23: Merchant | B23: High | C23: Red cloth, iron, a second hull if paid | D23: Animals eat the margin | E23: Karlsefni. Trade-rich, forage-poor
A24: Hunter-boat | B24: Medium | C24: Fishing, sealing, Markland pilotage | D24: Weak build, weak diplomacy | E24: Better ring, worse joint
A25: Shipwright's kin | B25: Medium | C25: Hull repair, spare sail, timber grade | D25: Poor foragers | E25: The slipway is the fantasy

Sheet Systems
A1: VINLAND
A2: Systems contract · the economy the mini-games pay into
A4: System | B4: Rule | C4: Input knob | D4: Knob cell | E4: Output | F4: Phase | G4: Backlog
A5: Cargo hold | B5: 24 units. People 0.4, cow 1.5, sheep 0.4. Timber only fits if food was eaten. | C5: Knarr cargo units | D5: =Assumptions!B41 -> 24 | E5: What can sail | F5: Vertical slice | G5: F01
A6: Rations | B6: Full, half, bare bones. Animals have their own ration. Starve the bull, lose the trade good. | C6: Party size | D6: =Assumptions!B42 -> 24 | E6: Morale, sickness, milk | F6: Vertical slice | G6: F01, F46
A7: Drink | B7: Water spoils if a cask is breached. Sour whey keeps. | C7: Drink coverage | D7: =Assumptions!B44 -> 120 | E7: Sea endurance | F7: Vertical slice | G7: F37
A8: Legs | B8: Eriksfjord, Labrador Sea, Helluland, Markland, Furðustrandir, Strait. Hóp is a second summer push. | C8: Open-water nm | D8: =Assumptions!B46 -> 400 | E8: Landfall quality | F8: Production | G8: F11, F27
A9: Watches | B9: Four hours. A good day is six watches if the fix held. | C9: Day's sail nm | D9: =Assumptions!B45 -> 120 | E9: Leg length | F9: Vertical slice | G9: F02
A10: Pace | B10: Crack on, easy, heave to. Heave to is the storm choice. | C10: — | D10: Design | E10: Sail strain, distance | F10: Vertical slice | G10: F38
A11: Drift | B11: No fix, ship walks downwind. Partial fix halves drift. Clean fix refunds it. | C11: — | D11: Mini-game | E11: Extra days, wrong landfall | F11: Vertical slice | G11: F03, F38
A12: Weather deck | B12: Fog, low cloud, following gale, beam sea, storm, drift ice, calm. Shuffled per leg. | C12: — | D12: Content | E12: Which verb is offered | F12: Production | G12: F09
A13: Fishing | B13: Once a day, coastal only. Fresh spoils in three days at sea unless dried on two fair days. | C13: Food coverage | D13: =Assumptions!B43 -> 168 | E13: Food units | F13: Vertical slice | G13: F05, F14, F15
A14: Hay | B14: Cut in late summer or the byre is a tomb. Mild winter is a climate die, not the default. | C14: Winters | D14: =Assumptions!B48 -> 2 | E14: Livestock survival | F14: Production | G14: F16, F47
A15: Goodwill / fear | B15: Trade raises goodwill. Weapon sale, killing, palisade, loose bull raise fear. | C15: Fear cap | D15: =Assumptions!B50 -> 5 | E15: Market or battle | F15: Production | G15: F19, F20, F21
A16: Return gate | B16: Boat shed, seaworthy hull, at least four timber units or equivalent. | C16: Timber to open return | D16: =Assumptions!B49 -> 4 | E16: Route unlock | F16: Alpha | G16: F24, F25
A17: Recruitment | B17: A living crew with a true story recruits better than silver. | C17: Summers | D17: =Assumptions!B47 -> 3 | E17: Second hull | F17: Alpha | G17: F26
A18: Score | B18: Cargo delivered, people alive in both places, goodwill left on the table. | C18: — | D18: Design | E18: Qualified vs full win | F18: Beta | G18: F31, F56
A19: Season clock | B19: Late-May departure, September last open water. Each watch and each camp day ticks. Still at sea in October is a loss. | C19: Full game length | D19: =Assumptions!B47 -> 3 | E19: Departure window, winter onset | F19: Vertical slice | G19: F35
A20: Ship condition | B20: Crack on strains the sail. Storm cards can spring a strake. A repair costs a camp day; a knarr that runs a storm pays twice. | C20: — | D20: Design | E20: Storm risk, repair days | F20: Production | G20: F45
A21: Sickness and morale | B21: Bare-bones rations, wet watches, and deaths move morale. Sick crew cannot stand a watch or take a verb. | C21: Party size | D21: =Assumptions!B42 -> 24 | E21: Who can work | F21: Production | G21: F46
A22: Livestock | B22: Cattle take 1.5 units, sheep 0.4. Fodder at sea, hay in camp. Milk is the trade good that keeps the peace. | C22: Cattle at departure | D22: =Assumptions!B57 -> 2 | E22: Milk, hides, the bull event | F22: Production | G22: F16
A23: Winter camp | B23: Hay, dried food, and shelter checked each winter week. A byre keeps the herd; a longhouse keeps the people. | C23: Winters | D23: =Assumptions!B48 -> 2 | E23: Survival, spring strength | F23: Production | G23: F47
A24: Hold check | B24: Departure load must fit the hull; the return must fit the timber gate. The HoldCheck sheet proves both from the knobs. | C24: Knarr cargo units | D24: =Assumptions!B41 -> 24 | E24: Ship-ready or not | F24: Vertical slice | G24: F01, F53

Sheet HoldCheck
A1: VINLAND
A2: Hold check · does the default load fit the knarr, and does the timber fit going home
A4: CROSSING LENGTH
A5: Item | B5: Value | C5: Note
A6: Route distance (nm) | B6: =Assumptions!B62 -> 1200 | C6: Assumptions hold knobs
A7: Good day's sail (nm) | B7: =Assumptions!B45 -> 120 | C7: Six watches with a held fix
A8: Clean sailing days | B8: =IF(B7=0,0,B6/B7) -> 10 | C8: Every fix clean, no weather
A9: Weather and lost-day factor | B9: =Assumptions!B63 -> 1.3 | C9: Fog, drift, heave-to
A10: Planned crossing days | B10: =ROUNDUP(B8*B9,0) -> 13 | C10: What the hold must feed
A12: DEPARTURE LOAD · ERIKSFJORD
A13: Line | B13: Count | C13: Units each | D13: Cargo units | E13: Rule
A14: People | B14: =Assumptions!B42 -> 24 | C14: =Assumptions!B54 -> 0.4 | D14: =B14*C14 -> 9.6 | E14: Party size on Assumptions
A15: Cattle | B15: =Assumptions!B57 -> 2 | C15: =Assumptions!B55 -> 1.5 | D15: =B15*C15 -> 3 | E15: Bull included
A16: Sheep and goats | B16: =Assumptions!B58 -> 6 | C16: =Assumptions!B56 -> 0.4 | D16: =B16*C16 -> 2.4
A17: Food units | B17: =ROUNDUP(B14*$B$10/Assumptions!B43,0) -> 2 | C17: 1 | D17: =B17*C17 -> 2 | E17: People × crossing days ÷ person-days per food unit
A18: Drink units | B18: =ROUNDUP(B14*$B$10/Assumptions!B44,0) -> 3 | C18: 1 | D18: =B18*C18 -> 3 | E18: People × crossing days ÷ person-days per drink unit
A19: Fodder units | B19: =ROUNDUP((B15+B16*Assumptions!B60)*$B$10/Assumptions!B59,0) -> 2 | C19: 1 | D19: =B19*C19 -> 2 | E19: Cattle-equivalents × crossing days ÷ cattle-days per fodder unit
A20: Trade goods | B20: =Assumptions!B61 -> 2 | C20: 1 | D20: =B20*C20 -> 2 | E20: Red cloth and iron
A21: Total departure load | D21: =SUM(D14:D20) -> 24
A22: Hull capacity | D22: =Assumptions!B41 -> 24
A23: Spare at departure | D23: =ROUND(D22-D21,2) -> 0 | E23: =IF(D23<0,"Over: leave a passenger, an animal, or a trade good",IF(D23<1,"Full: the intended feel","Room to spare: the hold is not yet a choice")) -> Full: the intended feel
A25: RETURN · TIMBER HOME
A26: Line | B26: Count | C26: Units each | D26: Cargo units | E26: Rule
A27: Return crew | B27: =Assumptions!B64 -> 10 | C27: =Assumptions!B54 -> 0.4 | D27: =B27*C27 -> 4 | E27: The rest winter the camp
A28: Return food units | B28: =ROUNDUP(B27*$B$10/Assumptions!B43,0) -> 1 | C28: 1 | D28: =B28*C28 -> 1 | E28: Same crossing length as outbound
A29: Return drink units | B29: =ROUNDUP(B27*$B$10/Assumptions!B44,0) -> 2 | C29: 1 | D29: =B29*C29 -> 2
A30: Load before timber | D30: =SUM(D27:D29) -> 7
A31: Room for timber | D31: =Assumptions!B41-D30 -> 17
A32: Most timber units that fit | D32: =INT(D31/Assumptions!B65) -> 17
A33: Timber units to open the return | D33: =Assumptions!B49 -> 4
A34: Return gate | D34: =IF(D32>=D33,"Opens","Blocked") -> Opens | E34: =IF(D32>=D33,"Room for "&D32&" timber units against a gate of "&D33,"Shrink the return crew or the crossing") -> Room for 17 timber units against a gate of 4
A36: One food, drink, fodder, or trade unit is one cargo unit by definition. Outbound food is eaten by landfall, which is why timber only fits going home. Tune the knobs on Assumptions; this sheet holds no inputs.

Sheet MiniGames
A1: VINLAND
A2: Mini-game production plan · gamepad-first, one grammar
A4: ID | B4: Verb | C4: Game | D4: Controls | E4: Difficulty is | F4: Success pays | G4: Failure costs | H4: Build order | I4: Backlog | J4: Haptic tell | K4: No-haptic fallback
A5: MG1 | B5: Navigate | C5: Star ring | D5: LS holds ring, RS seats Pole Star, RT raise, LT lower, B abort to partial | E5: Cloud gaps and a false horizon glow | F5: Drift refunded | G5: Ship walks downwind | H5: 1 | I5: F03 | J5: Pulse sharpens as the Pole Star seats; goes slack through cloud | K5: Ring rim brightens and a soft tick sounds when seated
A6: MG2 | B6: Navigate | C6: Sun board | D6: LS turns disk, RS sets peg, RT holds through the roll | E6: Overcast skips it; snatching the shadow keeps yesterday's error | F6: Latitude error shrinks | G6: Error carries | H6: 2 | I6: F04 | J6: Low hum when the shadow tip crosses the gnomon curve | K6: Shadow tip glints; result line names the error in degrees
A7: MG3 | B7: Fish | C7: Hand line | D7: LS pays line, RT sets on the ease, B cuts the line | E7: Current, fog hiding the bite | F7: Meals, hook kept | G7: Hook stock or the fish | H7: 1 | I7: F05 | J7: Bite is a two-beat tug on the left motor; the ease is a release | K7: Line twitches, float dips, bite sound on its own channel
A8: MG4 | B8: Fish | C8: Net | D8: RS throws the arc, both triggers close | E8: School depth in rain; fog until it is under the boat | F8: A day's meals, dryable | G8: Empty throw, day spent | H8: 3 | I8: F14 | J8: Weight builds in both triggers as the school comes under | K8: Water darkens and the surface boils over the school
A9: MG5 | B9: Hunt | C9: Stalk and loose | D9: LS move, RT speed, LB crouch, RB bow, RS lead, A loose, B lower | E9: Noise, wind in the grass, slick draw in rain | F9: Meat and a hide | G9: Wound, or a fear tick if ranging far | H9: 2 | I9: F12 | J9: Heartbeat when the animal is alert; draw resistance on RT | K9: Ear-flick icon on the animal; bowstring creak at full draw
A10: MG6 | B10: Forage | C10: Patch reading | D10: LS walk, RT take, RS sorts the basket | E10: Greedy hold strips the season; bird-island noise meter | F10: Food or a cargo marker | G10: Empty patch, or a vine eaten as calories | H10: 3 | I10: F13 | J10: Soft tick per take, harsh buzz when the take turns greedy | K10: Patch thins in color; basket weight bar on screen edge
A11: MG7 | B11: Build | C11: Joint | D11: LS brace, RS sets peg, RT drives with the grain | E11: Rain shortens the safe drive; grain reported on the trigger | F11: Joint seats, day counts | G11: Split log, day lost | H11: 2 | I11: F07 | J11: Grain resistance rises through RT when driving across it | K11: Grain line on the log turns red when the drive is cross-grain
A12: MG8 | B12: Build | C12: Lift | D12: Both triggers haul, LS braces, B sets down safe | E12: Sway window; surf on the slipway | F12: Wall or mast up | G12: Sick list, cracked timber | H12: 3 | I12: F18 | J12: Sway rhythm alternates between triggers | K12: Rope tension meter at screen edge with a safe band
A13: MG9 | B13: Build | C13: Smoke rack fire | D13: RS keeps the column under the wind | E13: Wind shove, too-hot case hardening | F13: Fish becomes a food unit | G13: Spoiled rack | H13: 4 | I13: F15 | J13: Warmth ramps up; a stutter when the fire case-hardens | K13: Smoke shifts from white to black as heat runs high
A14: MG10 | B14: Sea | C14: Storm bail | D14: No sky game. Hull check, then bail rhythm on RT | E14: Wave sets; skipped ring | F14: Hull holds, blind drift next | G14: Sprung strake, lost cask, man overboard | H14: 2 | I14: F10 | J14: Wave sets arrive as a rolling rumble one beat early | K14: Bucket metronome and a water line on the hull
A16: GAMEPAD GRAMMAR · DO NOT BREAK
A17: Left stick | B17: Gross motion: steer, sweep, draw, place, walk
A18: Right stick | B18: Fine correction: trim, lead, seat a joint, sort a basket
A19: RT | B19: Force or commitment. Haptic is the information channel.
A20: LT | B20: Brake, brace, or a lesser safe result
A21: RB / LB | B21: Swap tool. No wheel.
A22: A | B22: Bite, loose, plant. A commitment.
A23: B | B23: Emergency drop. Saves the person, spends the attempt.
A25: Every haptic tell needs a visual or audio twin before G4 (Backlog F32, Risk R3).

Sheet Backlog
A1: VINLAND
A2: Feature backlog · must-ship is the vertical promise plus the return
A4: ID | B4: Feature | C4: System | D4: Phase | E4: Priority | F4: Owner | G4: Estimate (days) | H4: Depends on | I4: Status | J4: Acceptance
A5: F41 | B5: Paper prototype: star ring and hold | C5: Navigate | D5: Preproduction | E5: Must | F5: Design | G5: 5 | H5: — | I5: Done | J5: Someone who did not design it finds a fix and argues about the hold. [Digital ring prototype stood in for the paper test.]
A6: F42 | B6: Engine bake-off: ring prototype in both engines | C6: Tech | D6: Preproduction | E6: Must | F6: Engineering | G6: 8 | H6: F41 | I6: Done | J6: Engine chosen by week 2 on ring feel and haptic API, not feature lists. [Godot 4.3 chosen 17 Oct 2026 without a bake-off: free, exports PC and web, builds headless for automated tests.]
A7: F43 | B7: Source control, build pipeline, tagged builds | C7: Tech | D7: Preproduction | E7: Must | F7: Engineering | G7: 3 | H7: F42 | I7: Done | J7: Every playtest build is reproducible from a tag. [Repo, tagged-quality builds, headless tests, Windows and Web exports.]
A8: F44 | B8: Art style target: one sea, one camp, one UI frame | C8: Art | D8: Preproduction | E8: Must | F8: Art | G8: 5 | H8: — | I8: Not started | J8: Three paintovers approved: wood, wool, and a ring, not chrome.
A9: F01 | B9: Hold and ration model | C9: Economy | D9: Vertical slice | E9: Must | F9: Engineering | G9: 8 | H9: — | I9: In progress | J9: Cargo units, rations, and spoilage read from Assumptions knobs; no literals in code. [Hold, rations, spoilage and animal fodder run from knobs; HoldCheck arithmetic reproduced and tested.]
A10: F02 | B10: Watch and leg runner | C10: Voyage | D10: Vertical slice | E10: Must | F10: Engineering | G10: 10 | H10: F01 | I10: In progress | J10: Four-hour watches advance a leg; pace and weather resolve per watch. [Six watches a day, six legs, landfalls, playable voyage screen from Eriksfjord to the Strait.]
A11: F03 | B11: Star ring mini-game | C11: Navigate | D11: Vertical slice | E11: Must | F11: Design | G11: 12 | H11: F02 | I11: Done | J11: Fix result (clean, partial, none) feeds drift; playable with haptics off. [Star ring passed the slice playtest after the difficulty retune.]
A12: F04 | B12: Sun board mini-game | C12: Navigate | D12: Vertical slice | E12: Must | F12: Design | G12: 6 | H12: F03 | I12: Not started | J12: Overcast skips it; a snatched shadow keeps yesterday's error.
A13: F05 | B13: Hand-line fishing | C13: Fish | D13: Vertical slice | E13: Must | F13: Design | G13: 8 | H13: F02 | I13: Done | J13: A bite reads through the trigger; a cut line keeps the hook. [Hand line passed the slice playtest after the difficulty retune.]
A14: F06 | B14: One camp day loop | C14: Colony | D14: Vertical slice | E14: Must | F14: Design | G14: 8 | H14: F01 | I14: Done | J14: Morning job queue, one verb, evening tally that changes the hold. [Camp day loop shipped in the slice and extended to a full year.]
A15: F07 | B15: Joint construction | C15: Build | D15: Vertical slice | E15: Must | F15: Engineering | G15: 8 | H15: F06 | I15: Done | J15: Grain reported on RT; a split log costs the day. [Joint passed the slice playtest after the difficulty retune.]
A16: F08 | B16: Gamepad grammar and haptics pass | C16: Controls | D16: Vertical slice | E16: Must | F16: Engineering | G16: 6 | H16: F03 | I16: In progress | J16: Every verb follows the grammar table on MiniGames; no verb invents a button. [Gamepad grammar mapped as input actions with keyboard fallback.]
... A69: F62 | B69: Crash reporting and day-one patch buffer | C69: Release | D69: Polish and ship | E69: Must | F69: Engineering | G69: 3 | H69: F57 | I69: Not started | J69: Crash logs reach the studio; one patch staged before launch.
D82: Total estimate (days) | G82: =SUM(G$5:G$80) -> 351
D83: Must-ship days | G83: =SUMIF(E$5:E$80,"Must",G$5:G$80) -> 306
D84: Should / could days | G84: =SUMIF(E$5:E$80,"Should",G$5:G$80)+SUMIF(E$5:E$80,"Could",G$5:G$80) -> 45
D85: Done days | G85: =SUMIF(I$5:I$80,"Done",G$5:G$80) -> 52
D86: Must-ship done | G86: =IF(G83=0,0,SUMIFS(G$5:G$80,E$5:E$80,"Must",I$5:I$80,"Done")/G83) -> 0.16993464
A89: CAPACITY CHECK · FEATURE DAYS AGAINST BUDGETED PERSON-WEEKS
A90: Owner | C90: Backlog days | D90: Capacity (days) | E90: Load | F90: Read
A91: Design | C91: =SUMIF(F$5:F$80,A91,G$5:G$80) -> 166 | D91: =TeamBudget!I5*5 -> 200 | E91: =IF(D91=0,0,C91/D91) -> 0.83 | F91: =IF(E91>0.8,"Over",IF(E91>0.6,"Tight","OK")) -> Over
A92: Engineering | C92: =SUMIF(F$5:F$80,A92,G$5:G$80) -> 137 | D92: =TeamBudget!I6*5 -> 220 | E92: =IF(D92=0,0,C92/D92) -> 0.62272727 | F92: =IF(E92>0.8,"Over",IF(E92>0.6,"Tight","OK")) -> Tight
A93: Art | C93: =SUMIF(F$5:F$80,A93,G$5:G$80) -> 18 | D93: =TeamBudget!I7*5 -> 155 | E93: =IF(D93=0,0,C93/D93) -> 0.11612903 | F93: =IF(E93>0.8,"Over",IF(E93>0.6,"Tight","OK")) -> OK
A94: Audio | C94: =SUMIF(F$5:F$80,A94,G$5:G$80) -> 10 | D94: =TeamBudget!I8*5 -> 60 | E94: =IF(D94=0,0,C94/D94) -> 0.16666667 | F94: =IF(E94>0.8,"Over",IF(E94>0.6,"Tight","OK")) -> OK
A95: QA | C95: =SUMIF(F$5:F$80,A95,G$5:G$80) -> 4 | D95: =TeamBudget!I9*5 -> 90 | E95: =IF(D95=0,0,C95/D95) -> 0.044444444 | F95: =IF(E95>0.8,"Over",IF(E95>0.6,"Tight","OK")) -> OK
A96: Production | C96: =SUMIF(F$5:F$80,A96,G$5:G$80) -> 16 | D96: =TeamBudget!I10*5 -> 160 | E96: =IF(D96=0,0,C96/D96) -> 0.1 | F96: =IF(E96>0.8,"Over",IF(E96>0.6,"Tight","OK")) -> OK
A97: All owners | C97: =SUM(C91:C96) -> 351 | D97: =SUM(D91:D96) -> 885 | E97: =IF(D97=0,0,C97/D97) -> 0.39661017 | F97: =IF(E97>0.8,"Over",IF(E97>0.6,"Tight","OK")) -> OK
A99: Phase | C99: Backlog days | D99: Person-days | E99: Load | F99: Read
A100: =Assumptions!A16 -> Preproduction | C100: =SUMIF(D$5:D$80,A100,G$5:G$80) -> 21 | D100: =TeamBudget!I15*5 -> 80 | E100: =IF(D100=0,0,C100/D100) -> 0.2625 | F100: =IF(E100>0.8,"Over",IF(E100>0.6,"Tight","OK")) -> OK
A101: =Assumptions!A17 -> Vertical slice | C101: =SUMIF(D$5:D$80,A101,G$5:G$80) -> 91 | D101: =TeamBudget!I16*5 -> 170 | E101: =IF(D101=0,0,C101/D101) -> 0.53529412 | F101: =IF(E101>0.8,"Over",IF(E101>0.6,"Tight","OK")) -> OK
A102: =Assumptions!A18 -> Production | C102: =SUMIF(D$5:D$80,A102,G$5:G$80) -> 151 | D102: =TeamBudget!I17*5 -> 320 | E102: =IF(D102=0,0,C102/D102) -> 0.471875 | F102: =IF(E102>0.8,"Over",IF(E102>0.6,"Tight","OK")) -> OK
A103: =Assumptions!A19 -> Alpha | C103: =SUMIF(D$5:D$80,A103,G$5:G$80) -> 54 | D103: =TeamBudget!I18*5 -> 130 | E103: =IF(D103=0,0,C103/D103) -> 0.41538462 | F103: =IF(E103>0.8,"Over",IF(E103>0.6,"Tight","OK")) -> OK
A104: =Assumptions!A20 -> Beta | C104: =SUMIF(D$5:D$80,A104,G$5:G$80) -> 25 | D104: =TeamBudget!I19*5 -> 115 | E104: =IF(D104=0,0,C104/D104) -> 0.2173913 | F104: =IF(E104>0.8,"Over",IF(E104>0.6,"Tight","OK")) -> OK
A105: =Assumptions!A21 -> Polish and ship | C105: =SUMIF(D$5:D$80,A105,G$5:G$80) -> 9 | D105: =TeamBudget!I20*5 -> 70 | E105: =IF(D105=0,0,C105/D105) -> 0.12857143 | F105: =IF(E105>0.8,"Over",IF(E105>0.6,"Tight","OK")) -> OK
A107: Estimates are feature-build days only. Iteration, bug fixing, content, and meetings live in the remaining capacity, so a load above 60% is tight and above 80% will slip. Fix by cutting Could items, moving a row to a later phase, or adding weeks on Assumptions.

Sheet Schedule
A1: VINLAND
A2: Phase schedule · dates flow from Assumptions
A4: Phase | B4: Weeks | C4: Start | D4: End | E4: Exit gate | F4: Demo | G4: Risk if slipped | H4: Gate
A5: =Assumptions!A16 -> Preproduction | B5: =Assumptions!B16 -> 8 | C5: =Assumptions!B8 -> 46328 | D5: =C5+B5*7-1 -> 46383 | E5: Pillar doc signed. Paper ring playable on a table. Slice scope frozen. | F5: Internal table read | G5: Scope still soft. Do not hire the full art week yet. | H5: G0
A6: =Assumptions!A17 -> Vertical slice | B6: =Assumptions!B17 -> 10 | C6: =D5+1 -> 46384 | D6: =C6+B6*7-1 -> 46453 | E6: One sea leg, a fix, a fish, a joint, a hold that changed because of them. | F6: Playable slice, friends | G6: If the ring is not fun, stop. Nothing downstream saves a bad fix. | H6: G1
A7: =Assumptions!A18 -> Production | B7: =Assumptions!B18 -> 18 | C7: =D6+1 -> 46454 | D7: =C7+B7*7-1 -> 46579 | E7: All six legs, five verbs, market, hay, slipway. No new verbs after this. | F7: External playtest 1 | G7: Hóp and sealing are the relief valves. | H7: G2
A8: =Assumptions!A19 -> Alpha | B8: =Assumptions!B19 -> 6 | C8: =D7+1 -> 46580 | D8: =C8+B8*7-1 -> 46621 | E8: Feature complete. One three-summer run from outfit to score. | F8: External playtest 2 | G8: Economy exploits become the work. | H8: G3
A9: =Assumptions!A20 -> Beta | B9: =Assumptions!B20 -> 6 | C9: =D8+1 -> 46622 | D9: =C9+B9*7-1 -> 46663 | E9: Difficulty and accessibility locked. Content freeze. | F9: Release candidate | G9: No new events. Tune only. | H9: G4
A10: =Assumptions!A21 -> Polish and ship | B10: =Assumptions!B21 -> 4 | C10: =D9+1 -> 46664 | D10: =C10+B10*7-1 -> 46691 | E10: Store page live. Trailer cut. Day-one patch list empty enough to ship. | F10: Ship | G10: A slipped ship date costs the autumn window in the marketing story, not the design. | H10: G5
A12: Ship date | B12: =D10 -> 46691
A13: Days, plan date to ship | B13: =B12-Assumptions!B7 -> 387
A14: MILESTONE CALENDAR CHECK
A15: The start date and the six week counts live on Assumptions. This sheet only adds. If a phase overruns, add weeks there, do not type a date here.
A16: Holidays are not carved out of phase weeks. This plan crosses Thanksgiving, the December holidays, and summer. Budget one rest week per phase by adding it on Assumptions (Risk R13).

Sheet Timeline
A1: VINLAND
A2: Timeline · week by week from Schedule; add weeks on Assumptions and the bars move
A4: Week | B4: Start | C4: End | D4: 1 | E4: 2 | F4: 3 | G4: 4 | H4: 5 | I4: 6 | J4: 7 | K4: 8 | L4: 9 | M4: 10 | N4: 11 | O4: 12 | P4: 13 | Q4: 14 | R4: 15 | S4: 16 | T4: 17 | U4: 18 | V4: 19 | W4: 20 | X4: 21 | Y4: 22 | Z4: 23 | AA4: 24 | AB4: 25 | AC4: 26 | AD4: 27 | AE4: 28 | AF4: 29 | AG4: 30 | AH4: 31 | AI4: 32 | AJ4: 33 | AK4: 34 | AL4: 35 | AM4: 36 | AN4: 37 | AO4: 38 | AP4: 39 | AQ4: 40 | AR4: 41 | AS4: 42 | AT4: 43 | AU4: 44 | AV4: 45 | AW4: 46 | AX4: 47 | AY4: 48 | AZ4: 49 | BA4: 50 | BB4: 51 | BC4: 52 | BD4: 53 | BE4: 54 | BF4: 55 | BG4: 56 | BH4: 57 | BI4: 58 | BJ4: 59 | BK4: 60
A5: Week of | D5: =Assumptions!$B$8+(D$4-1)*7 -> 46328 | E5: =Assumptions!$B$8+(E$4-1)*7 -> 46335 | F5: =Assumptions!$B$8+(F$4-1)*7 -> 46342 | G5: =Assumptions!$B$8+(G$4-1)*7 -> 46349 | H5: =Assumptions!$B$8+(H$4-1)*7 -> 46356 | I5: =Assumptions!$B$8+(I$4-1)*7 -> 46363 | J5: =Assumptions!$B$8+(J$4-1)*7 -> 46370 | K5: =Assumptions!$B$8+(K$4-1)*7 -> 46377 | ... BK5: =Assumptions!$B$8+(BK$4-1)*7 -> 46741
A6: Month | D6: =TEXT(D5,"mmm") -> Nov | E6: =IF(MONTH(E5)<>MONTH(D5),TEXT(E5,"mmm"),"") | F6: =IF(MONTH(F5)<>MONTH(E5),TEXT(F5,"mmm"),"") | G6: =IF(MONTH(G5)<>MONTH(F5),TEXT(G5,"mmm"),"") | H6: =IF(MONTH(H5)<>MONTH(G5),TEXT(H5,"mmm"),"") | I6: =IF(MONTH(I5)<>MONTH(H5),TEXT(I5,"mmm"),"") -> Dec | J6: =IF(MONTH(J5)<>MONTH(I5),TEXT(J5,"mmm"),"") | K6: =IF(MONTH(K5)<>MONTH(J5),TEXT(K5,"mmm"),"") | L6: =IF(MONTH(L5)<>MONTH(K5),TEXT(L5,"mmm"),"") | ... BK6: =IF(MONTH(BK5)<>MONTH(BJ5),TEXT(BK5,"mmm"),"")
A7: =Schedule!A5 -> Preproduction | B7: =Schedule!C5 -> 46328 | C7: =Schedule!D5 -> 46383 | D7: =IF(AND(D$5+6>=$B7,D$5<=$C7),1,"") -> 1 | E7: =IF(AND(E$5+6>=$B7,E$5<=$C7),1,"") -> 1 | F7: =IF(AND(F$5+6>=$B7,F$5<=$C7),1,"") -> 1 | G7: =IF(AND(G$5+6>=$B7,G$5<=$C7),1,"") -> 1 | H7: =IF(AND(H$5+6>=$B7,H$5<=$C7),1,"") -> 1 | I7: =IF(AND(I$5+6>=$B7,I$5<=$C7),1,"") -> 1 | J7: =IF(AND(J$5+6>=$B7,J$5<=$C7),1,"") -> 1 | K7: =IF(AND(K$5+6>=$B7,K$5<=$C7),1,"") -> 1 | ... BK7: =IF(AND(BK$5+6>=$B7,BK$5<=$C7),1,"")
A8: =Schedule!A6 -> Vertical slice | B8: =Schedule!C6 -> 46384 | C8: =Schedule!D6 -> 46453 | D8: =IF(AND(D$5+6>=$B8,D$5<=$C8),1,"") | E8: =IF(AND(E$5+6>=$B8,E$5<=$C8),1,"") | F8: =IF(AND(F$5+6>=$B8,F$5<=$C8),1,"") | G8: =IF(AND(G$5+6>=$B8,G$5<=$C8),1,"") | H8: =IF(AND(H$5+6>=$B8,H$5<=$C8),1,"") | I8: =IF(AND(I$5+6>=$B8,I$5<=$C8),1,"") | J8: =IF(AND(J$5+6>=$B8,J$5<=$C8),1,"") | K8: =IF(AND(K$5+6>=$B8,K$5<=$C8),1,"") | ... BK8: =IF(AND(BK$5+6>=$B8,BK$5<=$C8),1,"")
A9: =Schedule!A7 -> Production | B9: =Schedule!C7 -> 46454 | C9: =Schedule!D7 -> 46579 | D9: =IF(AND(D$5+6>=$B9,D$5<=$C9),1,"") | E9: =IF(AND(E$5+6>=$B9,E$5<=$C9),1,"") | F9: =IF(AND(F$5+6>=$B9,F$5<=$C9),1,"") | G9: =IF(AND(G$5+6>=$B9,G$5<=$C9),1,"") | H9: =IF(AND(H$5+6>=$B9,H$5<=$C9),1,"") | I9: =IF(AND(I$5+6>=$B9,I$5<=$C9),1,"") | J9: =IF(AND(J$5+6>=$B9,J$5<=$C9),1,"") | K9: =IF(AND(K$5+6>=$B9,K$5<=$C9),1,"") | ... BK9: =IF(AND(BK$5+6>=$B9,BK$5<=$C9),1,"")
A10: =Schedule!A8 -> Alpha | B10: =Schedule!C8 -> 46580 | C10: =Schedule!D8 -> 46621 | D10: =IF(AND(D$5+6>=$B10,D$5<=$C10),1,"") | E10: =IF(AND(E$5+6>=$B10,E$5<=$C10),1,"") | F10: =IF(AND(F$5+6>=$B10,F$5<=$C10),1,"") | G10: =IF(AND(G$5+6>=$B10,G$5<=$C10),1,"") | H10: =IF(AND(H$5+6>=$B10,H$5<=$C10),1,"") | I10: =IF(AND(I$5+6>=$B10,I$5<=$C10),1,"") | J10: =IF(AND(J$5+6>=$B10,J$5<=$C10),1,"") | K10: =IF(AND(K$5+6>=$B10,K$5<=$C10),1,"") | ... BK10: =IF(AND(BK$5+6>=$B10,BK$5<=$C10),1,"")
A11: =Schedule!A9 -> Beta | B11: =Schedule!C9 -> 46622 | C11: =Schedule!D9 -> 46663 | D11: =IF(AND(D$5+6>=$B11,D$5<=$C11),1,"") | E11: =IF(AND(E$5+6>=$B11,E$5<=$C11),1,"") | F11: =IF(AND(F$5+6>=$B11,F$5<=$C11),1,"") | G11: =IF(AND(G$5+6>=$B11,G$5<=$C11),1,"") | H11: =IF(AND(H$5+6>=$B11,H$5<=$C11),1,"") | I11: =IF(AND(I$5+6>=$B11,I$5<=$C11),1,"") | J11: =IF(AND(J$5+6>=$B11,J$5<=$C11),1,"") | K11: =IF(AND(K$5+6>=$B11,K$5<=$C11),1,"") | ... BK11: =IF(AND(BK$5+6>=$B11,BK$5<=$C11),1,"")
A12: =Schedule!A10 -> Polish and ship | B12: =Schedule!C10 -> 46664 | C12: =Schedule!D10 -> 46691 | D12: =IF(AND(D$5+6>=$B12,D$5<=$C12),1,"") | E12: =IF(AND(E$5+6>=$B12,E$5<=$C12),1,"") | F12: =IF(AND(F$5+6>=$B12,F$5<=$C12),1,"") | G12: =IF(AND(G$5+6>=$B12,G$5<=$C12),1,"") | H12: =IF(AND(H$5+6>=$B12,H$5<=$C12),1,"") | I12: =IF(AND(I$5+6>=$B12,I$5<=$C12),1,"") | J12: =IF(AND(J$5+6>=$B12,J$5<=$C12),1,"") | K12: =IF(AND(K$5+6>=$B12,K$5<=$C12),1,"") | ... BK12: =IF(AND(BK$5+6>=$B12,BK$5<=$C12),1,"")
A13: Gates | D13: =IF(SUMPRODUCT((Milestones!$B$5:$B$10>=D$5)*(Milestones!$B$5:$B$10<=D$5+6))>0,"◆","") | E13: =IF(SUMPRODUCT((Milestones!$B$5:$B$10>=E$5)*(Milestones!$B$5:$B$10<=E$5+6))>0,"◆","") | F13: =IF(SUMPRODUCT((Milestones!$B$5:$B$10>=F$5)*(Milestones!$B$5:$B$10<=F$5+6))>0,"◆","") | G13: =IF(SUMPRODUCT((Milestones!$B$5:$B$10>=G$5)*(Milestones!$B$5:$B$10<=G$5+6))>0,"◆","") | H13: =IF(SUMPRODUCT((Milestones!$B$5:$B$10>=H$5)*(Milestones!$B$5:$B$10<=H$5+6))>0,"◆","") | I13: =IF(SUMPRODUCT((Milestones!$B$5:$B$10>=I$5)*(Milestones!$B$5:$B$10<=I$5+6))>0,"◆","") | J13: =IF(SUMPRODUCT((Milestones!$B$5:$B$10>=J$5)*(Milestones!$B$5:$B$10<=J$5+6))>0,"◆","") | K13: =IF(SUMPRODUCT((Milestones!$B$5:$B$10>=K$5)*(Milestones!$B$5:$B$10<=K$5+6))>0,"◆","") -> ◆ | ... BK13: =IF(SUMPRODUCT((Milestones!$B$5:$B$10>=BK$5)*(Milestones!$B$5:$B$10<=BK$5+6))>0,"◆","")
A14: This week | D14: =IF(AND(TODAY()>=D$5,TODAY()<=D$5+6),"▲","") | E14: =IF(AND(TODAY()>=E$5,TODAY()<=E$5+6),"▲","") | F14: =IF(AND(TODAY()>=F$5,TODAY()<=F$5+6),"▲","") | G14: =IF(AND(TODAY()>=G$5,TODAY()<=G$5+6),"▲","") | H14: =IF(AND(TODAY()>=H$5,TODAY()<=H$5+6),"▲","") | I14: =IF(AND(TODAY()>=I$5,TODAY()<=I$5+6),"▲","") | J14: =IF(AND(TODAY()>=J$5,TODAY()<=J$5+6),"▲","") | K14: =IF(AND(TODAY()>=K$5,TODAY()<=K$5+6),"▲","") | ... BK14: =IF(AND(TODAY()>=BK$5,TODAY()<=BK$5+6),"▲","")
A16: ="Ship lands in week "&ROUNDUP((Schedule!B12-Assumptions!B8+1)/7,0)&" of 60 shown. ◆ marks the week a gate falls due; ▲ marks the current week." -> Ship lands in week 52 of 60 shown. ◆ marks the week a gate falls due; ▲ marks the current week.

Sheet TeamBudget
A1: VINLAND
A2: Team loading and cost · weeks are inputs, rates come from Assumptions
A4: Role | B4: Rate / week | C4: Preproduction | D4: Vertical slice | E4: Production | F4: Alpha | G4: Beta | H4: Polish and ship | I4: Person-weeks | J4: Labor
A5: Design | B5: =Assumptions!B26 -> 1800 | C5: 6 | D5: 8 | E5: 14 | F5: 6 | G5: 4 | H5: 2 | I5: =SUM(C5:H5) -> 40 | J5: =B5*I5 -> 72000
A6: Engineering | B6: =Assumptions!B27 -> 2200 | C6: 4 | D6: 10 | E6: 18 | F6: 6 | G6: 4 | H6: 2 | I6: =SUM(C6:H6) -> 44 | J6: =B6*I6 -> 96800
A7: Art | B7: =Assumptions!B28 -> 1700 | C7: 2 | D7: 6 | E7: 14 | F7: 4 | G7: 3 | H7: 2 | I7: =SUM(C7:H7) -> 31 | J7: =B7*I7 -> 52700
A8: Audio | B8: =Assumptions!B29 -> 1600 | C8: 0 | D8: 2 | E8: 4 | F8: 2 | G8: 2 | H8: 2 | I8: =SUM(C8:H8) -> 12 | J8: =B8*I8 -> 19200
A9: QA | B9: =Assumptions!B30 -> 1200 | C9: 0 | D9: 2 | E9: 4 | F9: 4 | G9: 6 | H9: 2 | I9: =SUM(C9:H9) -> 18 | J9: =B9*I9 -> 21600
A10: Production | B10: =Assumptions!B31 -> 1900 | C10: 4 | D10: 6 | E10: 10 | F10: 4 | G10: 4 | H10: 4 | I10: =SUM(C10:H10) -> 32 | J10: =B10*I10 -> 60800
A11: Person-weeks per phase | B11: sum of roles | C11: =SUM(C5:C10) -> 16 | D11: =SUM(D5:D10) -> 34 | E11: =SUM(E5:E10) -> 64 | F11: =SUM(F5:F10) -> 26 | G11: =SUM(G5:G10) -> 23 | H11: =SUM(H5:H10) -> 14 | I11: =SUM(I5:I10) -> 177 | J11: =SUM(J5:J10) -> 323100
A12: Average team size (FTE) | B12: person-weeks ÷ weeks | C12: =IF(Assumptions!B16=0,0,C11/Assumptions!B16) -> 2 | D12: =IF(Assumptions!B17=0,0,D11/Assumptions!B17) -> 3.4 | E12: =IF(Assumptions!B18=0,0,E11/Assumptions!B18) -> 3.5555556 | F12: =IF(Assumptions!B19=0,0,F11/Assumptions!B19) -> 4.3333333 | G12: =IF(Assumptions!B20=0,0,G11/Assumptions!B20) -> 3.8333333 | H12: =IF(Assumptions!B21=0,0,H11/Assumptions!B21) -> 3.5 | I12: =IF(Assumptions!B22=0,0,I11/Assumptions!B22) -> 3.4038462
A13: PHASE ROLLUP · DASHBOARD READS THIS BLOCK
A14: Phase | B14: Calendar weeks | C14: Design | D14: Engineering | E14: Art | F14: Audio | G14: QA | H14: Production | I14: Person-weeks | J14: Labor
A15: =Assumptions!A16 -> Preproduction | B15: =Assumptions!B16 -> 8 | C15: =C5 -> 6 | D15: =C6 -> 4 | E15: =C7 -> 2 | F15: =C8 -> 0 | G15: =C9 -> 0 | H15: =C10 -> 4 | I15: =SUM(C15:H15) -> 16 | J15: =C15*Assumptions!$B$26+D15*Assumptions!$B$27+E15*Assumptions!$B$28+F15*Assumptions!$B$29+G15*Assumptions!$B$30+H15*Assumptions!$B$31 -> 30600
A16: =Assumptions!A17 -> Vertical slice | B16: =Assumptions!B17 -> 10 | C16: =D5 -> 8 | D16: =D6 -> 10 | E16: =D7 -> 6 | F16: =D8 -> 2 | G16: =D9 -> 2 | H16: =D10 -> 6 | I16: =SUM(C16:H16) -> 34 | J16: =C16*Assumptions!$B$26+D16*Assumptions!$B$27+E16*Assumptions!$B$28+F16*Assumptions!$B$29+G16*Assumptions!$B$30+H16*Assumptions!$B$31 -> 63600
A17: =Assumptions!A18 -> Production | B17: =Assumptions!B18 -> 18 | C17: =E5 -> 14 | D17: =E6 -> 18 | E17: =E7 -> 14 | F17: =E8 -> 4 | G17: =E9 -> 4 | H17: =E10 -> 10 | I17: =SUM(C17:H17) -> 64 | J17: =C17*Assumptions!$B$26+D17*Assumptions!$B$27+E17*Assumptions!$B$28+F17*Assumptions!$B$29+G17*Assumptions!$B$30+H17*Assumptions!$B$31 -> 118800
A18: =Assumptions!A19 -> Alpha | B18: =Assumptions!B19 -> 6 | C18: =F5 -> 6 | D18: =F6 -> 6 | E18: =F7 -> 4 | F18: =F8 -> 2 | G18: =F9 -> 4 | H18: =F10 -> 4 | I18: =SUM(C18:H18) -> 26 | J18: =C18*Assumptions!$B$26+D18*Assumptions!$B$27+E18*Assumptions!$B$28+F18*Assumptions!$B$29+G18*Assumptions!$B$30+H18*Assumptions!$B$31 -> 46400
A19: =Assumptions!A20 -> Beta | B19: =Assumptions!B20 -> 6 | C19: =G5 -> 4 | D19: =G6 -> 4 | E19: =G7 -> 3 | F19: =G8 -> 2 | G19: =G9 -> 6 | H19: =G10 -> 4 | I19: =SUM(C19:H19) -> 23 | J19: =C19*Assumptions!$B$26+D19*Assumptions!$B$27+E19*Assumptions!$B$28+F19*Assumptions!$B$29+G19*Assumptions!$B$30+H19*Assumptions!$B$31 -> 39100
A20: =Assumptions!A21 -> Polish and ship | B20: =Assumptions!B21 -> 4 | C20: =H5 -> 2 | D20: =H6 -> 2 | E20: =H7 -> 2 | F20: =H8 -> 2 | G20: =H9 -> 2 | H20: =H10 -> 4 | I20: =SUM(C20:H20) -> 14 | J20: =C20*Assumptions!$B$26+D20*Assumptions!$B$27+E20*Assumptions!$B$28+F20*Assumptions!$B$29+G20*Assumptions!$B$30+H20*Assumptions!$B$31 -> 24600
A21: Labor subtotal | J21: =SUM(J15:J20) -> 323100
A22: Overhead | I22: =Assumptions!B32 -> 0.15 | J22: =J21*I22 -> 48465
A23: Outsource art | J23: =Assumptions!B34 -> 18000
A24: Music and foley | J24: =Assumptions!B35 -> 12000
A25: Store, trailer, legal | J25: =Assumptions!B36 -> 4000
A26: Playtest honoraria | J26: =Assumptions!B37 -> 2500
A27: Cultural and historical consultant | J27: =Assumptions!B76 -> 3000
A28: Platform fee (Steam Direct) | J28: =Assumptions!B75 -> 100
A29: Subtotal before contingency | J29: =SUM(J21:J28) -> 411165
A30: Contingency | I30: =Assumptions!B33 -> 0.12 | J30: =J29*I30 -> 49339.8
A31: FULLY LOADED | J31: =J29+J30 -> 460504.8
A33: Dashboard and Breakeven link
A34: B35 is the labor subtotal, B36 is fully loaded, B37 is cash outlay excluding labor (with contingency). Dashboard and Breakeven read these three cells.
A35: Labor subtotal | B35: =J21 -> 323100
A36: Fully loaded | B36: =J31 -> 460504.8
A37: Cash outlay excl. labor | B37: =SUM(J22:J28)*(1+I30) -> 98632.8

Sheet Breakeven
A1: VINLAND
A2: Break-even · what the plan costs in copies sold
A4: NET PER UNIT
A5: Item | B5: Value | C5: Note
A6: List price | B6: =Assumptions!B69 -> 19.99 | C6: Assumptions
A7: Realized price | B7: =B6*Assumptions!B70 -> 15.992 | C7: After launch discounts, regional pricing, sales-tax netting
A8: After refunds | B8: =B7*(1-Assumptions!B71) -> 14.71264
A9: Blended store share | B9: =Assumptions!B72*(1-Assumptions!B74)+Assumptions!B73*Assumptions!B74 -> 0.29 | C9: Steam and itch.io weighted by the sales mix
A10: Net to studio per unit | B10: =B8*(1-B9) -> 10.445974 | C10: Before income tax
A12: BREAK-EVEN
A13: Item | B13: Value | C13: Note
A14: Fully loaded cost | B14: =TeamBudget!B36 -> 460504.8 | C14: Labor at market rates plus every cost line
A15: Units to break even, fully loaded | B15: =IF(B10=0,0,ROUNDUP(B14/B10,0)) -> 44085 | C15: Pays everyone at the rates on Assumptions
A16: Cash outlay excluding labor | B16: =TeamBudget!B37 -> 98632.8 | C16: Overhead, outsourcing, fees, contingency
A17: Units to recover cash | B17: =IF(B10=0,0,ROUNDUP(B16/B10,0)) -> 9443 | C17: The floor for a self-funded solo developer
A18: Gross sales at full break-even | B18: =B15*B6 -> 881259.15 | C18: List price × units, before every deduction
A20: SALES SCENARIOS
A21: Units sold | B21: Net revenue | C21: Vs fully loaded | D21: Vs cash outlay | E21: Read
A22: =Assumptions!B77 -> 2000 | B22: =A22*$B$10 -> 20891.949 | C22: =B22-$B$14 -> -439612.85 | D22: =B22-$B$16 -> -77740.851 | E22: =IF(C22>=0,"Pays everyone; funds the next hull",IF(D22>=0,"Cash back; labor partly unpaid","Short of cash")) -> Short of cash
A23: =Assumptions!B78 -> 5000 | B23: =A23*$B$10 -> 52229.872 | C23: =B23-$B$14 -> -408274.93 | D23: =B23-$B$16 -> -46402.928 | E23: =IF(C23>=0,"Pays everyone; funds the next hull",IF(D23>=0,"Cash back; labor partly unpaid","Short of cash")) -> Short of cash
A24: =Assumptions!B79 -> 10000 | B24: =A24*$B$10 -> 104459.74 | C24: =B24-$B$14 -> -356045.06 | D24: =B24-$B$16 -> 5826.944 | E24: =IF(C24>=0,"Pays everyone; funds the next hull",IF(D24>=0,"Cash back; labor partly unpaid","Short of cash")) -> Cash back; labor partly unpaid
A25: =Assumptions!B80 -> 25000 | B25: =A25*$B$10 -> 261149.36 | C25: =B25-$B$14 -> -199355.44 | D25: =B25-$B$16 -> 162516.56 | E25: =IF(C25>=0,"Pays everyone; funds the next hull",IF(D25>=0,"Cash back; labor partly unpaid","Short of cash")) -> Cash back; labor partly unpaid
A26: =Assumptions!B81 -> 50000 | B26: =A26*$B$10 -> 522298.72 | C26: =B26-$B$14 -> 61793.92 | D26: =B26-$B$16 -> 423665.92 | E26: =IF(C26>=0,"Pays everyone; funds the next hull",IF(D26>=0,"Cash back; labor partly unpaid","Short of cash")) -> Pays everyone; funds the next hull
A28: Labor rates price the work at market value. A solo developer drawing no salary needs only the cash line to stay whole; the fully loaded line is what the work is worth. Revenue inputs are planning assumptions on Assumptions, not a forecast. Income tax is not modeled.

Sheet Milestones
A1: VINLAND
A2: Milestone acceptance · a phase is done when the gate is true, not when the week ends
A4: Gate | B4: Phase end | C4: Must be true | D4: Evidence | E4: Owner | F4: Status | G4: Backlog proof | H4: Risks watched
A5: G0 | B5: =Schedule!D5 -> 46383 | C5: Pillars signed. Paper prototype of the ring judged fun by someone who did not design it. | D5: Digital ring prototype, 17 Oct 2026 | E5: Design | F5: Passed | G5: F41, F42, F43, F44 | H5: R8, R9
A6: G1 | B6: =Schedule!D6 -> 46453 | C6: Slice: leave a fjord, miss a fix, fish, dry nothing, build one joint, see the hold change. | D6: Slice build v2, playtest 17 Oct 2026 ("much better") | E6: Engineering | F6: Passed | G6: F01, F02, F03, F04, F05, F06, F07, F08, F35, F36, F37, F38, F39, F40, F61 | H6: R1, R2, R12, R16
A7: G2 | B7: =Schedule!D7 -> 46579 | C7: All verbs in, market can break, hay can kill the herd, slipway can spill a log. | D7: Playtest 1 report | E7: Design | F7: In progress | G7: F09, F10, F11, F12, F13, F14, F15, F16, F17, F18, F19, F20, F21, F22, F23, F45, F46, F47, F48, F49, F50, F51, F52, F53, F59, F63, F65 | H7: R4, R5, R6, R11, R13, R15
A8: G3 | B8: =Schedule!D8 -> 46621 | C8: Three-summer run completable. Qualified ending and full ending both reachable. | D8: Alpha save set | E8: Production | F8: Not started | G8: F24, F25, F26, F27, F28, F29, F30, F54, F55, F64 | H8: R7, R10
A9: G4 | B9: =Schedule!D9 -> 46663 | C9: Remap works. No-haptic fallback taught. No must-ship bug open. | D9: Beta bug list | E9: QA | F9: Not started | G9: F31, F32, F33, F56, F57, F58 | H9: R3, R14
A10: G5 | B10: =Schedule!D10 -> 46691 | C10: Ship build, trailer, store copy, day-one notes. | D10: Release folder | E10: Production | F10: Not started | G10: F34, F60, F62 | H10: —
A12: A gate is Passed only when every Must row in its Backlog proof is Done or formally Cut, and the evidence exists in the release folder.

Sheet Risks
A1: VINLAND
A2: Risks · score is likelihood times impact, both 1 to 5
A4: ID | B4: Risk | C4: Likelihood | D4: Impact | E4: Score | F4: Mitigation | G4: Owner | H4: Watch | I4: Early warning | J4: Status
A5: R1 | B5: Star ring is not fun | C5: 3 | D5: 5 | E5: =C5*D5 -> 15 | F5: Stop at the slice. Retune forgiveness before any other verb. [17 Oct 2026: first playtest failed every mini-game. Retuned: Forgiving / Standard / Hard difficulty, guided prompts, keyboard wind-up, novice-player bots now gate every build.] | G5: Design | H5: G1 | I5: Table testers stop seating stars after three tries | J5: Watching
A6: R2 | B6: Hold math is trivial or cruel | C6: 3 | D6: 4 | E6: =C6*D6 -> 12 | F6: Log every slice run. Tune food coverage on Assumptions, not in code literals. | G6: Design | H6: G1 | I6: Slice runs end with the hold always full or never touched | J6: Open
A7: R3 | B7: Haptics-only tells lock out players | C7: 2 | D7: 4 | E7: =C7*D7 -> 8 | F7: No-haptic fallback is must-ship, not a patch. | G7: Engineering | H7: G4 | I7: Testers with haptics off miss bites or split joints | J7: Open
A8: R4 | B8: Scope creep into a second site | C8: 4 | D8: 3 | E8: =C8*D8 -> 12 | F8: Hóp is Should. Cut it before cutting the return. | G8: Production | H8: G2 | I8: Hóp tasks show up in Production plans | J8: Open
A9: R5 | B9: Art style slips into illustration | C9: 2 | D9: 3 | E9: =C9*D9 -> 6 | F9: UI is wood, wool, and a ring. Outsource budget is capped on Assumptions. | G9: Art | H9: G2 | I9: Outsourced pieces come back painterly | J9: Open
A10: R6 | B10: Native trade reads as a shooter | C10: 2 | D10: 5 | E10: =C10*D10 -> 10 | F10: Market is the verb. The bow turns outward only after fear caps. | G10: Design | H10: G2 | I10: Testers reach for the bow before the market | J10: Open
A11: R7 | B11: Solo schedule slips a phase | C11: 3 | D11: 4 | E11: =C11*D11 -> 12 | F11: Add weeks on Assumptions. Do not silently eat polish. | G11: Production | H11: G3 | I11: Two straight weeks behind on backlog burn | J11: Open
A12: R8 | B12: Engine choice burns the slice | C12: 2 | D12: 4 | E12: =C12*D12 -> 8 | F12: Pick at week 2. Ring prototype is the decider, not a feature list. | G12: Engineering | H12: G0 | I12: No engine pick by the end of week 2 | J12: Open
A13: R9 | B13: Historical pedantry stalls play | C13: 2 | D13: 2 | E13: =C13*D13 -> 4 | F13: Saga disagreement is a footnote, not a blocker. Karlsefni spine is locked. | G13: Design | H13: G0 | I13: Design debates cite sagas more than playtests | J13: Open
A14: R10 | B14: Return voyage feels like a commute | C14: 3 | D14: 4 | E14: =C14*D14 -> 12 | F14: Autumn bias: longer nights, worse weather. The reversal is the content. | G14: Design | H14: G3 | I14: Testers autopilot or skip return legs | J14: Open
A15: R11 | B15: Indigenous people read as a prop or a stereotype | C15: 3 | D15: 5 | E15: =C15*D15 -> 15 | F15: Fund the consultant review before G2 (Backlog F59). Market visitors have wants of their own. Keep saga terms in saga-voice text with context, not as faction labels. | G15: Design | H15: G2 | I15: Consultant flags; visitors exist only to trade or fight | J15: Open
A16: R12 | B16: Store page goes up too late to build wishlists | C16: 4 | D16: 4 | E16: =C16*D16 -> 16 | F16: Store page live at the end of the slice (F61). One-leg demo for Steam Next Fest between Alpha and Beta. | G16: Production | H16: G1 | I16: Wishlists flat for a month after the page goes live | J16: Open
... A20: R16 | B20: Cash runs out before ship | C20: 3 | D20: 5 | E20: =C20*D20 -> 15 | F20: Breakeven reviewed at every gate. Phase cost share on Dashboard is the burn check. Cut order applies to spend as well as scope. | G20: Production | H20: G1 | I20: Spend runs ahead of the phase share on Dashboard | J20: Open

Sheet Content
A1: VINLAND
A2: Content pipeline · what has to exist before a phase can exit
A4: Bucket | B4: Slice need | C4: Production need | D4: Ship need | E4: Notes | F4: Owner | G4: Outsource?
A5: Sky | B5: One clear night, one clouded | C5: Fog false glow, twilight short night, storm skip | D5: Autumn return sky | E5: Stars are marks, not a planetarium | F5: Art | G5: Ships and UI frames, sky plates
A6: Sea | B6: One coastal leg, one calm | C6: Ice, beam sea, gale, calm oars | D6: Autumn storm bias | E6: Legs are a chain, not an open map | F6: Design / Art | G6: No
A7: Camp | B7: Booth footprint | C7: Byre, longhouse, rack, palisade, slip | D7: Worn winter camp | E7: Job queue, not a tech tree | F7: Art | G7: No
A8: Creatures | B8: One fish | C8: Salmon, deer, birds, bull | D8: Seal for hunter outfit | E8: No bestiary screen | F8: Art | G8: Creature models if over budget
A9: People | B9: Crew silhouettes | C9: Four outfits, named roles, market visitors | D9: Second-summer recruits | E9: Women are roles, not passengers | F9: Art | G9: Silhouette pass only
A10: UI | B10: Ring, hold tally | C10: Rations, fear, season | D10: Score and saga ending | E10: Wood and wool, not chrome | F10: Art | G10: UI frames (Assumptions B34)
A11: Audio | B11: Wind, one bite, mallet click | C11: Hull creak, market, hay scythe | D11: Return theme, trailer stem | E11: Haptic first, speaker second | F11: Audio | G11: Music and foley (Assumptions B35)
A12: Words | B12: Fix result line | C12: Event lines, trade lines, birth | D12: Ending cards | E12: No scolding the historical ending | F12: Design | G12: No
A13: Haptics | B13: Ring seat, bite, grain | C13: One pattern per mini-game tell | D13: Tuned strengths, no-haptic twins | E13: Haptics are content, authored like sound | F13: Engineering | G13: No
A14: Store and marketing | B14: Slice screenshots, capsule draft | C14: Store page live, demo build | D14: Trailer, final capsules, press kit | E14: Trailer: fix in fog, a joint, timber leaving | F14: Production | G14: Capsule art
A15: Localization | B15: String table exists | C15: All text in the table | D15: English locked; second language if the date holds | E15: Icelandic names do not translate | F15: Production | G15: Translation, post-ship

Sheet Release
A1: VINLAND
A2: Release plan · PC, gamepad-first, a single-player run of three summers
A4: Item | B4: Decision | C4: When | D4: Owner
A5: Platform | B5: PC first. Gamepad required for the intended feel. Mouse is a fallback, not the target. | C5: G0 | D5: Production
A6: Engine | B6: Choose Godot 4 or Unity at week 2, based on which ships the ring prototype faster. | C6: Week 2 | D6: Engineering
A7: Save | B7: Watch-level autosave on the voyage. Day-level in camp. Ironman is a toggle, not the default. | C7: G2 | D7: Engineering
A8: Session | B8: A leg is a sitting. A summer is an evening. The full game is three evenings. | C8: G1 | D8: Design
A9: Price stance | B9: Premium single purchase. No energy, no hull repair packs. | C9: G0 | D9: Production
A10: Age and tone | B10: Trade can become a fight. No gore gallery. The bull and the birth are the tonal range. | C10: G2 | D10: Design
A11: Languages | B11: English at ship. Icelandic names kept. A second language only if the ship date holds. | C11: G4 | D11: Production
A12: Trailer | B12: One fix in fog, one joint, one timber cargo leaving the slip. | C12: G5 | D12: Production
A13: Day one | B13: Remap, no-haptic, and a known-issues note if the autumn bias is still sharp. | C13: G5 | D13: QA
A14: Post-ship | B14: No second site promised. A Markland fishing variant is the only safe follow-up. | C14: After ship | D14: Design
A15: Storefronts | B15: Steam is primary. itch.io carries the same build for players who already follow nickdoneysr there. The sales mix lives on Assumptions. | C15: G1 | D15: Production
A16: Price | B16: ="Premium at $"&TEXT(Assumptions!B69,"0.00")&". Launch discount no deeper than the realized-price factor on Assumptions." -> Premium at $19.99. Launch discount no deeper than the realized-price factor on Assumptions. | C16: G3 | D16: Production
A17: Wishlists | B17: Store page live at the end of the vertical slice so wishlists build for a full year before ship. | C17: G1 | D17: Production
A18: Demo | B18: One-leg demo built from the slice for Steam Next Fest between Alpha and Beta. Demo saves do not carry over. | C18: G3 | D18: Production
A19: Steam Deck | B19: Target Deck Verified: gamepad-native, legible text at 800p, no launcher. | C19: G4 | D19: Engineering
A20: Content rating | B20: Complete the store's content survey (and IARC where a store requires it) at Beta. Disclose trade violence and animal death. | C20: G4 | D20: Production
A21: Achievements | B21: Tied to saga beats and the full win, never to grinding. | C21: G4 | D21: Design
A22: Accessibility statement | B22: Store page lists remaps, no-haptic mode, hold-to-repeat, and text size. | C22: G5 | D22: Production

Sheet Revisions
A1: VINLAND
A2: Revision log · what changed in this pass and why
A4: Date | B4: Sheet | C4: Change | D4: Why
A5: 46311 | B5: TeamBudget | C5: Fixed the stale "Dashboard labor link" note (it pointed at H20 and H26) and removed a stray =J29 sitting in the Playtest honoraria row. | D5: The note sent readers to the wrong cells; the stray value looked like a cost.
A6: 46311 | B6: TeamBudget | C6: Renamed row 11 to "Person-weeks per phase" and added an average-team-size (FTE) row. | D6: Row 11 was labeled a check against Assumptions but only summed person-weeks.
A7: 46311 | B7: TeamBudget | C7: Added consultant and Steam Direct fee lines; Fully Loaded moved to J31 (named range updated); added cash outlay excluding labor (B37). | D7: Two real costs were missing; cash outlay drives the self-funded break-even.
A8: 46311 | B8: Assumptions | C8: Added hold loading knobs, release and revenue inputs, sales scenarios, project notes, and an expanded how-to-read block. | D8: Every new sheet reads its inputs from here, keeping one input sheet.
A9: 46311 | B9: Systems | C9: Added Season clock, Ship condition, Sickness and morale, Livestock, Winter camp, and Hold check rows, plus a Backlog column. | D9: Three clocks on Pillars had no system rows; every system now traces to backlog IDs.
A10: 46311 | B10: HoldCheck | C10: New sheet: departure load against the hull, return room against the timber gate. | D10: Proves the default party fits the knarr ("a hold that is already full") and that the return can open.
A11: 46311 | B11: MiniGames | C11: Added Backlog link, Haptic tell, and No-haptic fallback for all ten mini-games. | D11: Risk R3 and F32 require a no-haptic twin for every tell; none were specified.
A12: 46311 | B12: Backlog | C12: Grew from 34 to 65 items, added Status and Acceptance columns, phase/owner/status dropdowns, done tracking, and a capacity check by owner and phase. | D12: Preproduction had no rows; save, menus, audio, onboarding, season, hull, winter, review, and release work were missing.
A13: 46311 | B13: Schedule | C13: Added a Gate column, days from plan date to ship, and a holiday note. | D13: Ties dates to gates; the plan crosses three holiday periods with no rest weeks.
A14: 46311 | B14: Timeline | C14: New sheet: a 60-week bar chart driven by Schedule, with gate and current-week markers. | D14: A visual of the phase plan that redraws when weeks change.
A15: 46311 | B15: Breakeven | C15: New sheet: net per unit, break-even units (fully loaded and cash only), five sales scenarios. | D15: The plan had cost but no revenue view.
A16: 46311 | B16: Milestones | C16: Added Status (dropdown), Backlog proof, and Risks watched columns plus a pass rule. | D16: A gate now has a checkable definition of done.
... A20: 46311 | B20: Dashboard | C20: Backlog counts widened to the new range; break-even KPI added; Health Checks block with status colors. | D20: One page now shows scope load, hold math, revenue, risk, and gate status.
