Workbook

Sheet Summary
A1: VINLAND · ART
A2: Summary · how much art, when it is needed, and how much is done (reads the Status column)
A4: BY PHASE · PAINT IN THIS ORDER
A5: Phase | B5: Assets | C5: Must | D5: Hours | E5: Hours done | F5: Hours left | G5: Done | H5: Gate
A6: Preproduction | B6: =COUNTIF('Asset List'!$K$5:$K$262,A6) -> 6 | C6: =COUNTIFS('Asset List'!$K$5:$K$262,A6,'Asset List'!$L$5:$L$262,"Must") -> 5 | D6: =SUMIF('Asset List'!$K$5:$K$262,A6,'Asset List'!$O$5:$O$262) -> 33 | E6: =SUMIFS('Asset List'!$O$5:$O$262,'Asset List'!$K$5:$K$262,A6,'Asset List'!$P$5:$P$262,"Final")+SUMIFS('Asset List'!$O$5:$O$262,'Asset List'!$K$5:$K$262,A6,'Asset List'!$P$5:$P$262,"Imported") -> 0 | F6: =D6-E6 -> 33 | G6: =IF(D6=0,0,E6/D6) -> 0 | H6: G0
A7: Vertical slice | B7: =COUNTIF('Asset List'!$K$5:$K$262,A7) -> 88 | C7: =COUNTIFS('Asset List'!$K$5:$K$262,A7,'Asset List'!$L$5:$L$262,"Must") -> 85 | D7: =SUMIF('Asset List'!$K$5:$K$262,A7,'Asset List'!$O$5:$O$262) -> 367 | E7: =SUMIFS('Asset List'!$O$5:$O$262,'Asset List'!$K$5:$K$262,A7,'Asset List'!$P$5:$P$262,"Final")+SUMIFS('Asset List'!$O$5:$O$262,'Asset List'!$K$5:$K$262,A7,'Asset List'!$P$5:$P$262,"Imported") -> 0 | F7: =D7-E7 -> 367 | G7: =IF(D7=0,0,E7/D7) -> 0 | H7: G1
A8: Production | B8: =COUNTIF('Asset List'!$K$5:$K$262,A8) -> 127 | C8: =COUNTIFS('Asset List'!$K$5:$K$262,A8,'Asset List'!$L$5:$L$262,"Must") -> 106 | D8: =SUMIF('Asset List'!$K$5:$K$262,A8,'Asset List'!$O$5:$O$262) -> 737 | E8: =SUMIFS('Asset List'!$O$5:$O$262,'Asset List'!$K$5:$K$262,A8,'Asset List'!$P$5:$P$262,"Final")+SUMIFS('Asset List'!$O$5:$O$262,'Asset List'!$K$5:$K$262,A8,'Asset List'!$P$5:$P$262,"Imported") -> 0 | F8: =D8-E8 -> 737 | G8: =IF(D8=0,0,E8/D8) -> 0 | H8: G2
A9: Alpha | B9: =COUNTIF('Asset List'!$K$5:$K$262,A9) -> 16 | C9: =COUNTIFS('Asset List'!$K$5:$K$262,A9,'Asset List'!$L$5:$L$262,"Must") -> 6 | D9: =SUMIF('Asset List'!$K$5:$K$262,A9,'Asset List'!$O$5:$O$262) -> 63 | E9: =SUMIFS('Asset List'!$O$5:$O$262,'Asset List'!$K$5:$K$262,A9,'Asset List'!$P$5:$P$262,"Final")+SUMIFS('Asset List'!$O$5:$O$262,'Asset List'!$K$5:$K$262,A9,'Asset List'!$P$5:$P$262,"Imported") -> 0 | F9: =D9-E9 -> 63 | G9: =IF(D9=0,0,E9/D9) -> 0 | H9: G3
A10: Beta | B10: =COUNTIF('Asset List'!$K$5:$K$262,A10) -> 18 | C10: =COUNTIFS('Asset List'!$K$5:$K$262,A10,'Asset List'!$L$5:$L$262,"Must") -> 17 | D10: =SUMIF('Asset List'!$K$5:$K$262,A10,'Asset List'!$O$5:$O$262) -> 119 | E10: =SUMIFS('Asset List'!$O$5:$O$262,'Asset List'!$K$5:$K$262,A10,'Asset List'!$P$5:$P$262,"Final")+SUMIFS('Asset List'!$O$5:$O$262,'Asset List'!$K$5:$K$262,A10,'Asset List'!$P$5:$P$262,"Imported") -> 0 | F10: =D10-E10 -> 119 | G10: =IF(D10=0,0,E10/D10) -> 0 | H10: G4
A11: Polish and ship | B11: =COUNTIF('Asset List'!$K$5:$K$262,A11) -> 3 | C11: =COUNTIFS('Asset List'!$K$5:$K$262,A11,'Asset List'!$L$5:$L$262,"Must") -> 1 | D11: =SUMIF('Asset List'!$K$5:$K$262,A11,'Asset List'!$O$5:$O$262) -> 8 | E11: =SUMIFS('Asset List'!$O$5:$O$262,'Asset List'!$K$5:$K$262,A11,'Asset List'!$P$5:$P$262,"Final")+SUMIFS('Asset List'!$O$5:$O$262,'Asset List'!$K$5:$K$262,A11,'Asset List'!$P$5:$P$262,"Imported") -> 0 | F11: =D11-E11 -> 8 | G11: =IF(D11=0,0,E11/D11) -> 0 | H11: G5
A12: All phases | B12: =SUM(B6:B11) -> 258 | C12: =SUM(C6:C11) -> 220 | D12: =SUM(D6:D11) -> 1327 | E12: =SUM(E6:E11) -> 0 | F12: =SUM(F6:F11) -> 1327 | G12: =IF(D12=0,0,E12/D12) -> 0
A14: AGAINST THE PLAN
A15: Measure | B15: Value | C15: Source
A16: Art person-weeks in the plan | B16: 31 | C16: TeamBudget: Art row, all phases (from the plan workbook)
A17: Hours per person-week | B17: 40 | C17: Planning assumption; change it to your real week
A18: Planned art hours | B18: =B16*B17 -> 1240 | C18: Person-weeks × hours
A19: Estimated hours on this list | B19: =D12 -> 1327 | C19: Sum of the Est. hours column
A20: Hours flagged for outsourcing | B20: =SUMIF('Asset List'!$N$5:$N$262,"Yes",'Asset List'!$O$5:$O$262) -> 399 | C20: Rows marked Outsource "Yes"
A21: In-house hours if outsourcing happens | B21: =B19-B20 -> 928 | C21: What is left for you
A22: Fit (in-house hours ÷ planned hours) | B22: =IF(B18=0,0,B21/B18) -> 0.7483871 | C22: Over 100% means cut Could rows, outsource more, or add art weeks
A24: BY CATEGORY
A25: Category | B25: Assets | C25: Must | D25: Hours | E25: Hours done | F25: Hours left | G25: Done | H25: ID prefix
A26: Style targets | B26: =COUNTIF('Asset List'!$B$5:$B$262,A26) -> 6 | C26: =COUNTIFS('Asset List'!$B$5:$B$262,A26,'Asset List'!$L$5:$L$262,"Must") -> 5 | D26: =SUMIF('Asset List'!$B$5:$B$262,A26,'Asset List'!$O$5:$O$262) -> 33 | E26: =SUMIFS('Asset List'!$O$5:$O$262,'Asset List'!$B$5:$B$262,A26,'Asset List'!$P$5:$P$262,"Final")+SUMIFS('Asset List'!$O$5:$O$262,'Asset List'!$B$5:$B$262,A26,'Asset List'!$P$5:$P$262,"Imported") -> 0 | F26: =D26-E26 -> 33 | G26: =IF(D26=0,0,E26/D26) -> 0 | H26: STY
A27: Sky plates and celestial | B27: =COUNTIF('Asset List'!$B$5:$B$262,A27) -> 16 | C27: =COUNTIFS('Asset List'!$B$5:$B$262,A27,'Asset List'!$L$5:$L$262,"Must") -> 13 | D27: =SUMIF('Asset List'!$B$5:$B$262,A27,'Asset List'!$O$5:$O$262) -> 65 | E27: =SUMIFS('Asset List'!$O$5:$O$262,'Asset List'!$B$5:$B$262,A27,'Asset List'!$P$5:$P$262,"Final")+SUMIFS('Asset List'!$O$5:$O$262,'Asset List'!$B$5:$B$262,A27,'Asset List'!$P$5:$P$262,"Imported") -> 0 | F27: =D27-E27 -> 65 | G27: =IF(D27=0,0,E27/D27) -> 0 | H27: SKY
A28: Clouds and fog layers | B28: =COUNTIF('Asset List'!$B$5:$B$262,A28) -> 7 | C28: =COUNTIFS('Asset List'!$B$5:$B$262,A28,'Asset List'!$L$5:$L$262,"Must") -> 7 | D28: =SUMIF('Asset List'!$B$5:$B$262,A28,'Asset List'!$O$5:$O$262) -> 23 | E28: =SUMIFS('Asset List'!$O$5:$O$262,'Asset List'!$B$5:$B$262,A28,'Asset List'!$P$5:$P$262,"Final")+SUMIFS('Asset List'!$O$5:$O$262,'Asset List'!$B$5:$B$262,A28,'Asset List'!$P$5:$P$262,"Imported") -> 0 | F28: =D28-E28 -> 23 | G28: =IF(D28=0,0,E28/D28) -> 0 | H28: CLD
A29: Sea, ice and wildlife | B29: =COUNTIF('Asset List'!$B$5:$B$262,A29) -> 10 | C29: =COUNTIFS('Asset List'!$B$5:$B$262,A29,'Asset List'!$L$5:$L$262,"Must") -> 7 | D29: =SUMIF('Asset List'!$B$5:$B$262,A29,'Asset List'!$O$5:$O$262) -> 44 | E29: =SUMIFS('Asset List'!$O$5:$O$262,'Asset List'!$B$5:$B$262,A29,'Asset List'!$P$5:$P$262,"Final")+SUMIFS('Asset List'!$O$5:$O$262,'Asset List'!$B$5:$B$262,A29,'Asset List'!$P$5:$P$262,"Imported") -> 0 | F29: =D29-E29 -> 44 | G29: =IF(D29=0,0,E29/D29) -> 0 | H29: SEA
A30: Coasts by leg | B30: =COUNTIF('Asset List'!$B$5:$B$262,A30) -> 13 | C30: =COUNTIFS('Asset List'!$B$5:$B$262,A30,'Asset List'!$L$5:$L$262,"Must") -> 11 | D30: =SUMIF('Asset List'!$B$5:$B$262,A30,'Asset List'!$O$5:$O$262) -> 88 | E30: =SUMIFS('Asset List'!$O$5:$O$262,'Asset List'!$B$5:$B$262,A30,'Asset List'!$P$5:$P$262,"Final")+SUMIFS('Asset List'!$O$5:$O$262,'Asset List'!$B$5:$B$262,A30,'Asset List'!$P$5:$P$262,"Imported") -> 0 | F30: =D30-E30 -> 88 | G30: =IF(D30=0,0,E30/D30) -> 0 | H30: CST
A31: The knarr and other vessels | B31: =COUNTIF('Asset List'!$B$5:$B$262,A31) -> 13 | C31: =COUNTIFS('Asset List'!$B$5:$B$262,A31,'Asset List'!$L$5:$L$262,"Must") -> 12 | D31: =SUMIF('Asset List'!$B$5:$B$262,A31,'Asset List'!$O$5:$O$262) -> 52 | E31: =SUMIFS('Asset List'!$O$5:$O$262,'Asset List'!$B$5:$B$262,A31,'Asset List'!$P$5:$P$262,"Final")+SUMIFS('Asset List'!$O$5:$O$262,'Asset List'!$B$5:$B$262,A31,'Asset List'!$P$5:$P$262,"Imported") -> 0 | F31: =D31-E31 -> 52 | G31: =IF(D31=0,0,E31/D31) -> 0 | H31: SHP
A32: Weather and water effects | B32: =COUNTIF('Asset List'!$B$5:$B$262,A32) -> 7 | C32: =COUNTIFS('Asset List'!$B$5:$B$262,A32,'Asset List'!$L$5:$L$262,"Must") -> 6 | D32: =SUMIF('Asset List'!$B$5:$B$262,A32,'Asset List'!$O$5:$O$262) -> 14 | E32: =SUMIFS('Asset List'!$O$5:$O$262,'Asset List'!$B$5:$B$262,A32,'Asset List'!$P$5:$P$262,"Final")+SUMIFS('Asset List'!$O$5:$O$262,'Asset List'!$B$5:$B$262,A32,'Asset List'!$P$5:$P$262,"Imported") -> 0 | F32: =D32-E32 -> 14 | G32: =IF(D32=0,0,E32/D32) -> 0 | H32: WFX
A33: Navigation mini-games (star ring, sun board) | B33: =COUNTIF('Asset List'!$B$5:$B$262,A33) -> 10 | C33: =COUNTIFS('Asset List'!$B$5:$B$262,A33,'Asset List'!$L$5:$L$262,"Must") -> 10 | D33: =SUMIF('Asset List'!$B$5:$B$262,A33,'Asset List'!$O$5:$O$262) -> 36 | E33: =SUMIFS('Asset List'!$O$5:$O$262,'Asset List'!$B$5:$B$262,A33,'Asset List'!$P$5:$P$262,"Final")+SUMIFS('Asset List'!$O$5:$O$262,'Asset List'!$B$5:$B$262,A33,'Asset List'!$P$5:$P$262,"Imported") -> 0 | F33: =D33-E33 -> 36 | G33: =IF(D33=0,0,E33/D33) -> 0 | H33: NAV
A34: Fishing (hand line, net) | B34: =COUNTIF('Asset List'!$B$5:$B$262,A34) -> 11 | C34: =COUNTIFS('Asset List'!$B$5:$B$262,A34,'Asset List'!$L$5:$L$262,"Must") -> 9 | D34: =SUMIF('Asset List'!$B$5:$B$262,A34,'Asset List'!$O$5:$O$262) -> 53 | E34: =SUMIFS('Asset List'!$O$5:$O$262,'Asset List'!$B$5:$B$262,A34,'Asset List'!$P$5:$P$262,"Final")+SUMIFS('Asset List'!$O$5:$O$262,'Asset List'!$B$5:$B$262,A34,'Asset List'!$P$5:$P$262,"Imported") -> 0 | F34: =D34-E34 -> 53 | G34: =IF(D34=0,0,E34/D34) -> 0 | H34: FSH
A35: Hunting (stalk and loose) | B35: =COUNTIF('Asset List'!$B$5:$B$262,A35) -> 8 | C35: =COUNTIFS('Asset List'!$B$5:$B$262,A35,'Asset List'!$L$5:$L$262,"Must") -> 7 | D35: =SUMIF('Asset List'!$B$5:$B$262,A35,'Asset List'!$O$5:$O$262) -> 53 | E35: =SUMIFS('Asset List'!$O$5:$O$262,'Asset List'!$B$5:$B$262,A35,'Asset List'!$P$5:$P$262,"Final")+SUMIFS('Asset List'!$O$5:$O$262,'Asset List'!$B$5:$B$262,A35,'Asset List'!$P$5:$P$262,"Imported") -> 0 | F35: =D35-E35 -> 53 | G35: =IF(D35=0,0,E35/D35) -> 0 | H35: HNT
A36: Foraging (patch reading) | B36: =COUNTIF('Asset List'!$B$5:$B$262,A36) -> 8 | C36: =COUNTIFS('Asset List'!$B$5:$B$262,A36,'Asset List'!$L$5:$L$262,"Must") -> 5 | D36: =SUMIF('Asset List'!$B$5:$B$262,A36,'Asset List'!$O$5:$O$262) -> 40 | E36: =SUMIFS('Asset List'!$O$5:$O$262,'Asset List'!$B$5:$B$262,A36,'Asset List'!$P$5:$P$262,"Final")+SUMIFS('Asset List'!$O$5:$O$262,'Asset List'!$B$5:$B$262,A36,'Asset List'!$P$5:$P$262,"Imported") -> 0 | F36: =D36-E36 -> 40 | G36: =IF(D36=0,0,E36/D36) -> 0 | H36: FOR
A37: Building (joint, lift, smoke rack) | B37: =COUNTIF('Asset List'!$B$5:$B$262,A37) -> 14 | C37: =COUNTIFS('Asset List'!$B$5:$B$262,A37,'Asset List'!$L$5:$L$262,"Must") -> 14 | D37: =SUMIF('Asset List'!$B$5:$B$262,A37,'Asset List'!$O$5:$O$262) -> 58 | E37: =SUMIFS('Asset List'!$O$5:$O$262,'Asset List'!$B$5:$B$262,A37,'Asset List'!$P$5:$P$262,"Final")+SUMIFS('Asset List'!$O$5:$O$262,'Asset List'!$B$5:$B$262,A37,'Asset List'!$P$5:$P$262,"Imported") -> 0 | F37: =D37-E37 -> 58 | G37: =IF(D37=0,0,E37/D37) -> 0 | H37: BLD
... A52: Store and marketing art | B52: =COUNTIF('Asset List'!$B$5:$B$262,A52) -> 16 | C52: =COUNTIFS('Asset List'!$B$5:$B$262,A52,'Asset List'!$L$5:$L$262,"Must") -> 12 | D52: =SUMIF('Asset List'!$B$5:$B$262,A52,'Asset List'!$O$5:$O$262) -> 33 | E52: =SUMIFS('Asset List'!$O$5:$O$262,'Asset List'!$B$5:$B$262,A52,'Asset List'!$P$5:$P$262,"Final")+SUMIFS('Asset List'!$O$5:$O$262,'Asset List'!$B$5:$B$262,A52,'Asset List'!$P$5:$P$262,"Imported") -> 0 | F52: =D52-E52 -> 33 | G52: =IF(D52=0,0,E52/D52) -> 0 | H52: MKG
A54: BY STATUS
A55: Status | B55: Assets | C55: Hours
A56: Not started | B56: =COUNTIF('Asset List'!$P$5:$P$262,A56) -> 258 | C56: =SUMIF('Asset List'!$P$5:$P$262,A56,'Asset List'!$O$5:$O$262) -> 1327
A57: Sketch | B57: =COUNTIF('Asset List'!$P$5:$P$262,A57) -> 0 | C57: =SUMIF('Asset List'!$P$5:$P$262,A57,'Asset List'!$O$5:$O$262) -> 0
A58: In progress | B58: =COUNTIF('Asset List'!$P$5:$P$262,A58) -> 0 | C58: =SUMIF('Asset List'!$P$5:$P$262,A58,'Asset List'!$O$5:$O$262) -> 0
...

Sheet Slice First
A1: VINLAND · ART
A2: Start here · the art the vertical slice needs, in the order the build will use it
A4: ID | B4: Asset | C4: Export size | D4: Priority | E4: Hours | F4: Why now
A5: STY-01 | B5: Sea style target paintover | C5: 1920×1080 | D5: Must | E5: 10 | F5: Locks the look before anything else is finished (gate G0).
A6: STY-02 | B6: Camp style target paintover | C6: 1920×1080 | D6: Must | E6: 10 | F6: Locks the look before anything else is finished (gate G0).
A7: STY-03 | B7: UI style target paintover | C7: 1920×1080 | D7: Must | E7: 6 | F7: Locks the look before anything else is finished (gate G0).
A8: STY-04 | B8: Palette swatch sheet | C8: 1024×512 | D8: Must | E8: 2 | F8: Locks the look before anything else is finished (gate G0).
A9: STY-05 | B9: Character scale and proportion sheet | C9: 1920×1080 | D9: Must | E9: 4 | F9: Locks the look before anything else is finished (gate G0).
A10: STY-06 | B10: Greyscale readability test | C10: 1920×1080 | D10: Should | E10: 1 | F10: Locks the look before anything else is finished (gate G0).
A11: SKY-01 | B11: Sky plate: clear day | C11: 1920×1080 | D11: Must | E11: 5 | F11: The voyage and the star ring need these skies.
A12: SKY-03 | B12: Sky plate: fog | C12: 1920×1080 | D12: Must | E12: 4 | F12: The voyage and the star ring need these skies.
A13: SKY-06 | B13: Sky plate: summer twilight | C13: 1920×1080 | D13: Must | E13: 5 | F13: The voyage and the star ring need these skies.
A14: SKY-07 | B14: Sky plate: clear night | C14: 1920×1080 | D14: Must | E14: 5 | F14: The voyage and the star ring need these skies.
A15: SKY-08 | B15: Sky plate: clouded night | C15: 1920×1080 | D15: Must | E15: 4 | F15: The voyage and the star ring need these skies.
A16: SKY-13 | B16: Sky plate: camp summer and autumn | C16: 1920×1080 | D16: Must | E16: 7 | F16: The voyage and the star ring need these skies.
... A98: MKG-14 | B98: itch.io banner and page background | C98: 960×300, 1920×1080 | D98: Should | E98: 2 | F98: Store page goes up at G1 so wishlists build for a year.
B100: Slice art hours | E100: =SUM(E5:E98) -> 400

Sheet Art Spec
A1: VINLAND · ART
A2: Art spec · the rules every file follows so it drops straight into the Godot build
A4: HOW THIS LIST WORKS
A5: Every asset has an ID, an export size, and a file path. Save your finished PNG at exactly that path inside the project folder and the game picks it up on the next build. Until then the build uses a placeholder drawn at the same size, so nothing waits on art.
A6: Work in phase order. Vertical slice assets come first because the slice (one sea leg, a star fix, a fish, a camp day, one joint) is the go or no-go point of the whole project (gate G1).
A7: The Status column on Asset List is yours. Move each row through Not started, Sketch, In progress, Review, Final, and Imported. The Summary sheet counts hours done and left from it.
A8: Hours are first estimates for one artist painting at a finished-indie standard, including one revision. They exist to plan with; replace them with your own as you learn your pace.
A9: Rows marked Outsource "Yes" are the ones the plan's $18,000 outsource art budget was meant for: ships, UI frames, and sky plates on the plan, plus big background plates here.
A10: Market visitors and their boats, clothing, and goods stay as rough silhouettes until the cultural consultant has reviewed them (Backlog F59, Risk R11). Do not finish them early.
A12: GLOBAL EXPORT RULES
A13: Rule | B13: Specification | C13: Why | D13: Applies to
A14: Base resolution | B14: 1920×1080 game canvas. Godot stretch mode canvas_items, aspect expand. | C14: One art scale for every screen; 4K and 1440p scale up cleanly. | D14: Everything
A15: Steam Deck bleed | B15: Full-screen backgrounds are exported at 1920×1200: the central 1920×1080 is the safe area and 60 px of extra art sits above and below it. | C15: Steam Deck is 16:10. With bleed it shows more art instead of black bars. | D15: Background plates, illustrations used full screen
A16: Source resolution | B16: Paint at 2× (3840×2160 canvas) where you can, then export at the listed size. Keep layered source files (.kra, .psd) in art_source/. | C16: Lets store art and 4K screenshots reuse the same paintings. | D16: Plates, key art, portraits
A17: File format | B17: PNG, 8-bit RGBA, sRGB, straight (not premultiplied) alpha. JPG only where a store asks for it. | C17: Godot imports this without colour shifts. | D17: Everything
A18: Transparency | B18: Clean alpha edges with no halo: matte against the average background colour, never pure white or black. | C18: Prevents bright fringes on sprites over dark sea. | D18: Sprites, overlays
A19: No baked text | B19: No words painted into any asset except the logo. All text is drawn by the game. | C19: Localization and the font size option (F51, F63). | D19: Everything except the logo
A20: Sprite sheets | B20: One animation per file, frames left to right in a single row, every cell the same size, no padding. File name ends in _strip8 (frame count). | C20: Godot imports strips directly into SpriteFrames. | D20: Animated sprites
A21: Frame rate | B21: Creatures and people 12 fps; water, fire, and smoke loops 10 fps; UI 8 fps. Loops must loop without a pop. | C21: Painterly animation reads better on 12 than 24. | D21: Animations
A22: Cutout rigs | B22: Characters that move a lot are cutout rigs: each body part on its own layer, exported as separate PNGs in one folder, with a pivots.txt listing each part's joint point in pixels. | C22: Godot Skeleton2D animates them; one rig serves dozens of animations. | D22: Crew, hunter, visitors
A23: Pivots | B23: Ground-standing sprites: bottom centre. Floating objects: centre. Hanging objects: top centre. Water objects: the waterline. | C23: Code positions sprites by these points. | D23: Sprites
A24: 9-slice UI | B24: UI panels are 9-slice: the margin numbers in the Layers column are the unscaled border in pixels on each side. | C24: Panels resize to any text length. | D24: UI kit
... A27: Folders | B27: art/<category folder>/ as shown in the File path column, inside the Godot project folder. | C27: Matches the paths the build expects. | D27: Everything
A29: SCALE AND LINES THAT MUST MATCH
A30: Measure | B30: Value | C30: Where it is used | D30: Check against
A31: Voyage horizon line | B31: y = 620 (on the 1080 canvas) | C31: All voyage sky plates, sea bands, coast strips | D31: Sea style target
A32: Camp horizon line | B32: y = 540 | C32: Camp skies and camp far hills | D32: Camp style target
A33: Underwater surface line | B33: y = 260 | C33: Hand-line cross-section
A34: Adult at voyage scale | B34: about 110 px tall | C34: Crew on deck, distant figures | D34: Character scale sheet
A35: Adult at camp scale | B35: about 180 px tall | C35: Camp, market, lift | D35: Character scale sheet
A36: Adult at hunt scale | B36: about 340 px tall | C36: Hunter in the stalk scene | D36: Character scale sheet
A37: Cow at camp scale | B37: about 150 px at the shoulder | C37: Livestock | D37: Character scale sheet
A38: Knarr length at voyage scale | B38: about 1,400 px stem to stern | C38: Ship parts canvas 1600×1200 | D38: Sea style target
A39: Smallest readable icon | B39: 48 px on screen (painted at 128) | C39: HUD icons | D39: UI style target at 1280×800
A40: Body text | B40: 22 px minimum at 1080p | C40: All UI | D40: UI style target at 1280×800
A42: STARTING PALETTE · REFINE IT IN THE PALETTE SWATCH SHEET (STY-04)
A43: Name | B43: Hex | C43: Swatch | D43: Use
A44: Labrador slate | B44: #2F4A57 | D44: Deep sea, storm water
A45: North Atlantic grey-blue | B45: #5C7C8A | D45: Mid sea, overcast sky
A46: Fog white | B46: #DCE3E3 | D46: Fog, highlights on water
...

Sheet Scenes
A1: VINLAND · ART
A2: Scenes · where every asset sits, in draw order from back to front
A4: Scene | B4: Camera | C4: Layers, back to front | D4: Fixed positions | E4: Asset ID prefixes
A5: Voyage | B5: Side-on, static camera; the ship sits left of centre and bobs; the world scrolls past right to left. | C5: 1 sky plate · 2 sun or moon · 3 star field (night) · 4 cloud bands · 5 coast far strip · 6 icebergs far · 7 sea band far · 8 coast near strip · 9 ship (hull, mast, sail, oar, cargo, livestock, crew, damage) · 10 wake · 11 sea band near · 12 drift ice near · 13 weather FX (rain, spray, fog near) · 14 HUD | D5: Horizon y = 620. Ship waterline y = 760, ship centre x = 760. | E5: SKY, CLD, SEA, CST, SHP, WFX, HUD
A6: Star ring | B6: First person, looking north at the sky through the held ring; the view rolls with the ship. | C6: 1 night sky plate · 2 stars and Pole Star · 3 cloud gap overlay · 4 horizon line · 5 false horizon glow · 6 fog sheets · 7 ring · 8 seat glow · 9 hands · 10 result mark | D6: Ring centre at (960, 560). Pole Star placed by code. | E6: SKY, CLD, NAV
A7: Sun board | B7: Top-down at the dial floating in a bowl; the deck below is out of focus. | C7: 1 bowl and blurred deck · 2 dial · 3 gnomon curves · 4 gnomon shadow and tip · 5 peg · 6 overcast dimming · 7 hands (optional) | D7: Dial centre at (960, 540). | E7: NAV
A8: Hand line | B8: Split view: gunwale and surface at the top, underwater below. | C8: 1 underwater cross-section · 2 current particles · 3 fish · 4 hook, bait, sinker · 5 line (code) · 6 fog dimming · 7 gunwale and hands | D8: Surface y = 260. Hands bottom left. | E8: FSH, VFX
A9: Net | B9: Three-quarter view down into shallow water over the side of the boat. | C9: 1 shallow water · 2 fish school · 3 net throw arc · 4 rain overlay · 5 hauled net | D9: Landing area centre (960, 600). | E9: FSH
A10: Hunt | B10: Side-scrolling stalk across a meadow; the camera follows the hunter. | C10: 1 sky plate · 2 far layer · 3 mid layer · 4 animal · 5 hunter · 6 near grass strips · 7 wind streaks · 8 rain overlay | D10: Ground line y = 860. | E10: HNT, WFX
A11: Forage | B11: Top-down close-up of one patch. | C11: 1 patch background (state) · 2 pickups · 3 birds (bird cliff) · 4 reaching hand · 5 basket | D11: Basket bottom right at (1660, 860). | E11: FOR
A12: Joint | B12: Close-up on a trestle, low three-quarter angle. | C12: 1 workbench · 2 timber (wood type) · 3 grain line layer · 4 peg · 5 chips · 6 mallet and hands | D12: Mortise hole at (1010, 520). | E12: BLD
A13: Lift | B13: Side view of the shear legs at the building site or slipway. | C13: 1 camp sky · 2 lift background · 3 lifted timber · 4 rope (code) · 5 hauling crew · 6 slipway surf (slipway only) | D13: Block at (960, 180). | E13: BLD, CHR
A14: Smoke rack | B14: Close-up of the rack and fire from slightly below. | C14: 1 rack background · 2 fish on the rack · 3 fire · 4 smoke column · 5 wind shove FX | D14: Fire centre (960, 900). | E14: BLD
A15: Storm bail | B15: Inside the hold looking aft. | C15: 1 hull interior · 2 bilge water level · 3 lost cask · 4 leak jet · 5 bailing crew · 6 wave over the side · 7 metronome (haptics off) | D15: Water level range y 700–1000. | E15: BAL
... A21: Events and endings | B21: Card over a dimmed scene, or full screen for endings. | C21: 1 dimmed current scene · 2 event card frame · 3 illustration · 4 text and choices (code) | D21: Illustration window at (40, 40) inside the card. | E21: EVT, END, UIK

Sheet Asset List
A1: VINLAND · ART
A2: Asset list · every piece of art in the game, in category order; filter by Phase to see what is needed next
A4: ID | B4: Category | C4: Asset | D4: Description (what to paint) | E4: Used in | F4: Type | G4: Export size (px) | H4: Frames / states | I4: Layers, pivots, and notes | J4: File path | K4: Phase needed | L4: Priority | M4: Backlog | N4: Outsource? | O4: Est. hours | P4: Status | Q4: Your notes
A5: STY-01 | B5: Style targets | C5: Sea style target paintover | D5: Finished-quality frame of the voyage view at golden hour: knarr under full sail on a long swell, Markland forest on the horizon, crew silhouettes on deck. Sets brushwork, edge softness, value structure, and how much detail a 1080p frame carries. Every sea, sky, and ship asset is judged against it. | E5: Voyage | F5: Paintover | G5: 1920×1080 | H5: 1 | I5: Paint as separate layers in the voyage layer order (see Scenes) so it can be cut into real assets later. Keep the PSD/KRA. | J5: art_source/style/sty_01_sea_style_target_paintover.png | K5: Preproduction | L5: Must | M5: F44 | N5: No | O5: 10 | P5: Not started
A6: STY-02 | B6: Style targets | C6: Camp style target paintover | D6: Summer camp on the Strait shore: two booths raised, longhouse frame half up, bull tethered, smoke rack lit, knarr drawn up on the shingle. Sets the look of turf, timber, wool, and people at camp scale. | E6: Camp | F6: Paintover | G6: 1920×1080 | H6: 1 | I6: Layered in the camp layer order. Character scale is set here: an adult is about 180 px tall at camp scale. | J6: art_source/style/sty_02_camp_style_target_paintover.png | K6: Preproduction | L6: Must | M6: F44 | N6: No | O6: 10 | P6: Not started
A7: STY-03 | B7: Style targets | C7: UI style target paintover | D7: One HUD frame over the voyage view: hold tally stick, ration and pace selectors, season dial, one dialogue panel and two buttons. Wood, wool, and a ring; no chrome, no glow, no gradients that read as plastic. | E7: All | F7: Paintover | G7: 1920×1080 | H7: 1 | I7: Proves legibility of 22 px body text on painted wood. Check at 1280×800 (Steam Deck) as well. | J7: art_source/style/sty_03_ui_style_target_paintover.png | K7: Preproduction | L7: Must | M7: F44 | N7: No | O7: 6 | P7: Not started
A8: STY-04 | B8: Style targets | C8: Palette swatch sheet | D8: The master palette: 6 sea and sky blues, 5 turf and spruce greens, 4 wool creams, madder red (red cloth), iron grey, birch white, peat brown, whale-oil gold, plus the UI ink colour. Each with its hex code written under it. | E8: All | F8: Reference sheet | G8: 1024×512 | H8: 1 | I8: Also export as a .gpl (Krita/GIMP) or .ase (Photoshop) palette file beside the PNG. Starting values are on the Art Spec sheet. | J8: art_source/style/sty_04_palette_swatch_sheet.png | K8: Preproduction | L8: Must | M8: F44 | N8: No | O8: 2 | P8: Not started
A9: STY-05 | B9: Style targets | C9: Character scale and proportion sheet | D9: Line-up of the human body types (2 sexes × 3 builds), a child, a cow, a sheep, and the knarr hull, all at camp scale, with a 1 m measuring stick. Adults are slightly stylised (head about 1/7 of height) so poses read at small size. | E9: All | F9: Reference sheet | G9: 1920×1080 | H9: 1 | I9: Every character and animal asset is drawn to this sheet. | J9: art_source/style/sty_05_character_scale_and_proportion_sheet.png | K9: Preproduction | L9: Must | M9: F44 | N9: No | O9: 4 | P9: Not started
A10: STY-06 | B10: Style targets | C10: Greyscale readability test | D10: The sea and camp targets converted to greyscale, with the ship, people, and interactive objects checked for contrast against the background. Annotate any spot where the player could lose the ship or the cursor. | E10: All | F10: Reference sheet | G10: 1920×1080 | H10: 2 | I10: Not shipped. Keep for the art bible. | J10: art_source/style/sty_06_greyscale_readability_test.png | K10: Preproduction | L10: Should | M10: F44 | N10: No | O10: 1 | P10: Not started
A11: SKY-01 | B11: Sky plates and celestial | C11: Sky plate: clear day | D11: High-latitude summer day: pale cold blue at the zenith fading to a hazy, almost white horizon. A few high cirrus streaks only. Bright but never saturated. | E11: Voyage | F11: Background plate | G11: 1920×1200 (1080 safe) | H11: 1 | I11: Static, rearmost layer. Horizon line at y = 620 for all voyage sky plates so they swap without shifting. | J11: res://art/sky/sky_01_sky_plate_clear_day.png | K11: Vertical slice | L11: Must | M11: F02 | N11: Yes | O11: 5 | P11: Not started
A12: SKY-02 | B12: Sky plates and celestial | C12: Sky plate: overcast | D12: Flat grey-blue cloud deck with slightly darker undersides. The sun is a faint brighter patch only. Reads as no sun board today. | E12: Voyage | F12: Background plate | G12: 1920×1200 (1080 safe) | H12: 1 | I12: Horizon at y = 620. | J12: res://art/sky/sky_02_sky_plate_overcast.png | K12: Production | L12: Must | M12: F09 | N12: Yes | O12: 4 | P12: Not started
A13: SKY-03 | B13: Sky plates and celestial | C13: Sky plate: fog | D13: Near-white luminous fog that eats the horizon entirely; the sun is a pale disc that may or may not be there. Feels close and quiet. | E13: Voyage | F13: Background plate | G13: 1920×1200 (1080 safe) | H13: 1 | I13: Pairs with the fog sheet layers. Horizon is implied, not drawn. | J13: res://art/sky/sky_03_sky_plate_fog.png | K13: Vertical slice | L13: Must | M13: F09 | N13: Yes | O13: 4 | P13: Not started
A14: SKY-04 | B14: Sky plates and celestial | C14: Sky plate: low cloud | D14: Ragged scud racing low over the sea under a higher grey layer, with breaks of pale light. Used for the low-cloud weather card. | E14: Voyage | F14: Background plate | G14: 1920×1200 (1080 safe) | H14: 1 | I14: Horizon at y = 620. | J14: res://art/sky/sky_04_sky_plate_low_cloud.png | K14: Production | L14: Must | M14: F09 | N14: Yes | O14: 4 | P14: Not started
A15: SKY-05 | B15: Sky plates and celestial | C15: Sky plate: dawn | D15: Cold peach and lilac band along the horizon under a deep blue sky; last stars fading in the upper third. | E15: Voyage | F15: Background plate | G15: 1920×1200 (1080 safe) | H15: 1 | I15: Horizon at y = 620. | J15: res://art/sky/sky_05_sky_plate_dawn.png | K15: Production | L15: Should | M15: F35 | N15: Yes | O15: 4 | P15: Not started
A16: SKY-06 | B16: Sky plates and celestial | C16: Sky plate: summer twilight | D16: The short northern night: the sky never fully darkens, a lingering amber glow under the north horizon, a few bright stars. This is the hardest night for the star ring. | E16: Voyage, Star ring | F16: Background plate | G16: 1920×1200 (1080 safe) | H16: 1 | I16: Horizon at y = 620. Reused behind the star ring at reduced brightness. | J16: res://art/sky/sky_06_sky_plate_summer_twilight.png | K16: Vertical slice | L16: Must | M16: F03 | N16: Yes | O16: 5 | P16: Not started
... A212: EVT-08 | B212: Event and weather card illustrations | C212: Event: landfall | D212: The first sight of a new coast from the deck, the crew pointing. One per region is ideal; one shared image is the minimum. | E212: Events | F212: Illustration | G212: 800×450 | H212: 1 (up to 6) | I212: Could reuse the near coast strips with a crew foreground. | J212: res://art/events/evt_08_event_landfall.png | K212: Production | L212: Must | M212: F11 | N212: No | O212: 5 | P212: Not started
A213: EVT-09 | B213: Event and weather card illustrations | C213: Event: sprung strake | D213: A plank seam springing open, water jetting in, a crew member shoving a wad of wool into it. | E213: Events | F213: Illustration | G213: 800×450 | H213: 1 | J213: res://art/events/evt_09_event_sprung_strake.png | K213: Production | L213: Must | M213: F45 | N213: No | O213: 4 | P213: Not started
A214: EVT-10 | B214: Event and weather card illustrations | C214: Event: man overboard | D214: A figure in the water reaching up, a rope thrown from the gunwale. | E214: Events | F214: Illustration | G214: 800×450 | H214: 1 | I214: Not graphic. | J214: res://art/events/evt_10_event_man_overboard.png | K214: Production | L214: Must | M214: F10 | N214: No | O214: 4 | P214: Not started
A215: EVT-11 | B215: Event and weather card illustrations | C215: Event: cask breached | D215: A split water cask gushing across the deck. | E215: Events | F215: Illustration | G215: 800×450 | H215: 1 | J215: res://art/events/evt_11_event_cask_breached.png | K215: Vertical slice | L215: Must | M215: F37 | N215: No | O215: 3 | P215: Not started
A216: EVT-12 | B216: Event and weather card illustrations | C216: Event: sickness | D216: A crew member lying under a cloak in the hold, another giving them whey. | E216: Events | F216: Illustration | G216: 800×450 | H216: 1 | I216: Quiet tone. | J216: res://art/events/evt_12_event_sickness.png | K216: Production | L216: Must | M216: F46 | N216: No | O216: 4 | P216: Not started
A217: EVT-13 | B217: Event and weather card illustrations | C217: Event: a death | D217: Stones being set on a cairn at dusk, crew standing with heads bowed. | E217: Events | F217: Illustration | G217: 800×450 | H217: 1 | I217: Respectful, no body shown. | J217: res://art/events/evt_13_event_a_death.png | K217: Production | L217: Must | M217: F46 | N217: No | O217: 4 | P217: Not started
A218: EVT-14 | B218: Event and weather card illustrations | C218: Event: a birth | D218: Inside a booth by firelight, a mother holding a newborn, women around her. | E218: Events | F218: Illustration | G218: 800×450 | H218: 1 | I218: Warm, tender. | J218: res://art/events/evt_14_event_a_birth.png | K218: Production | L218: Should | M218: F48 | N218: No | O218: 4 | P218: Not started
A219: EVT-15 | B219: Event and weather card illustrations | C219: Event: the bull breaks loose | D219: The bull charging out of the byre toward the market blanket, visitors scattering. | E219: Events | F219: Illustration | G219: 800×450 | H219: 1 | I219: The saga moment; drama without violence. | J219: res://art/events/evt_15_event_the_bull_breaks_loose.png | K219: Production | L219: Must | M219: F21 | N219: No | O219: 5 | P219: Not started
A220: EVT-16 | B220: Event and weather card illustrations | C220: Event: the weapon request | D220: A visitor gesturing toward an iron blade on the trade blanket; a crew member hesitating. | E220: Events | F220: Illustration | G220: 800×450 | H220: 1 | I220: After consultant review. | J220: res://art/events/evt_16_event_the_weapon_request.png | K220: Production | L220: Must | M220: F21 | N220: No | O220: 4 | P220: Not started
A221: EVT-17 | B221: Event and weather card illustrations | C221: Event: market day arrives | D221: Skin boats landing on the shingle at morning, the camp coming out to meet them. | E221: Events | F221: Illustration | G221: 800×450 | H221: 1 | I221: After consultant review. | J221: res://art/events/evt_17_event_market_day_arrives.png | K221: Production | L221: Must | M221: F20 | N221: No | O221: 5 | P221: Not started
A222: EVT-18 | B222: Event and weather card illustrations | C222: Event: hay harvest | D222: Crew cutting tall grass with scythes in late-summer light. | E222: Events | F222: Illustration | G222: 800×450 | H222: 1 | J222: res://art/events/evt_18_event_hay_harvest.png | K222: Production | L222: Must | M222: F16 | N222: No | O222: 4 | P222: Not started
A223: EVT-19 | B223: Event and weather card illustrations | C223: Event: first snow | D223: The first snow settling on the turf roofs, smoke rising, livestock huddled. | E223: Events | F223: Illustration | G223: 800×450 | H223: 1 | J223: res://art/events/evt_19_event_first_snow.png | K223: Production | L223: Must | M223: F47 | N223: No | O223: 4 | P223: Not started
A224: EVT-20 | B224: Event and weather card illustrations | C224: Event: relief ship sighted | D224: A sail on the horizon, the camp running to the shore. | E224: Events | F224: Illustration | G224: 800×450 | H224: 1 | J224: res://art/events/evt_20_event_relief_ship_sighted.png | K224: Alpha | L224: Must | M224: F26 | N224: No | O224: 4 | P224: Not started
A225: EVT-21 | B225: Event and weather card illustrations | C225: Event: timber cargo departs | D225: The knarr loaded with timber pushing off from the slipway, waving crew. | E225: Events, trailer | F225: Illustration | G225: 800×450 | H225: 1 | I225: Also the trailer's closing image. | J225: res://art/events/evt_21_event_timber_cargo_departs.png | K225: Alpha | L225: Must | M225: F25 | N225: No | O225: 5 | P225: Not started
A226: EVT-22 | B226: Event and weather card illustrations | C226: Event: recruitment at Eriksfjord | D226: Crew retelling the voyage to a crowd at Brattahlíð; young people stepping forward. | E226: Events | F226: Illustration | G226: 800×450 | H226: 1 | J226: res://art/events/evt_22_event_recruitment_at_eriksfjord.png | K226: Alpha | L226: Must | M226: F26 | N226: No | O226: 4 | P226: Not started
A227: EVT-23 | B227: Event and weather card illustrations | C227: Event: Thorhall leaves | D227: A small party walking away along the shore, Thorhall in front. | E227: Events | F227: Illustration | G227: 800×450 | H227: 1 | I227: Only if F28 ships. | J227: res://art/events/evt_23_event_thorhall_leaves.png | K227: Alpha | L227: Could | M227: F28 | N227: No | O227: 4 | P227: Not started
A228: EVT-24 | B228: Event and weather card illustrations | C228: Event: grapes found at Hóp | D228: A crew member holding up a cluster of wild grapes, amazed. | E228: Events | F228: Illustration | G228: 800×450 | H228: 1 | J228: res://art/events/evt_24_event_grapes_found_at_hop.png | K228: Alpha | L228: Should | M228: F27 | N228: No | O228: 4 | P228: Not started
A229: EVT-25 | B229: Event and weather card illustrations | C229: Event: sealing | D229: Seals hauled out on an ice floe, a hunter creeping up. | E229: Events | F229: Illustration | G229: 800×450 | H229: 1 | I229: Only if F29 ships. | J229: res://art/events/evt_25_event_sealing.png | K229: Alpha | L229: Could | M229: F29 | N229: No | O229: 4 | P229: Not started
A230: END-01 | B230: Ending cards and score | C230: Ending: full win | D230: A living camp in spring: smoke from the longhouse, cattle out to graze, a relief ship anchored, children on the shore. The best ending. | E230: Ending | F230: Illustration | G230: 1920×1200 (1080 safe) | H230: 1 | I230: Full screen with a text panel overlay. | J230: res://art/endings/end_01_ending_full_win.png | K230: Beta | L230: Must | M230: F56 | N230: No | O230: 12 | P230: Not started
A231: END-02 | B231: Ending cards and score | C231: Ending: saga ending (leave rich) | D231: Both ships deep-laden pulling away from an empty camp, the booths already sagging. Rich but leaving; scored below a living camp, never scolded. | E231: Ending | F231: Illustration | G231: 1920×1080 | H231: 1 | I231: As above. | J231: res://art/endings/end_02_ending_saga_ending.png | K231: Beta | L231: Must | M231: F56 | N231: No | O231: 12 | P231: Not started
A232: END-03 | B232: Ending cards and score | C232: Ending: lost at sea | D232: October storm, a single broken spar on a grey sea. | E232: Ending | F232: Illustration | G232: 1920×1080 | H232: 1 | I232: As above. | J232: res://art/endings/end_03_ending_lost_at_sea.png | K232: Beta | L232: Must | M232: F56 | N232: No | O232: 10 | P232: Not started
A233: END-04 | B233: Ending cards and score | C233: Ending: winter starvation | D233: A snow-buried camp, no smoke, an empty byre door open. | E233: Ending | F233: Illustration | G233: 1920×1080 | H233: 1 | I233: As above. | J233: res://art/endings/end_04_ending_winter_starvation.png | K233: Beta | L233: Must | M233: F56 | N233: No | O233: 10 | P233: Not started
A234: END-05 | B234: Ending cards and score | C234: Ending: fear capped | D234: The palisade standing, the camp abandoned in haste, both hulls gone from the shore. | E234: Ending | F234: Illustration | G234: 1920×1080 | H234: 1 | I234: As above. | J234: res://art/endings/end_05_ending_fear_capped.png | K234: Beta | L234: Must | M234: F56 | N234: No | O234: 10 | P234: Not started
A235: END-06 | B235: Ending cards and score | C235: Score screen board | D235: A large carved board for the final tally: cargo delivered, people alive in both places, goodwill left. | E235: Score | F235: UI frame | G235: 1600×900 | H235: 1 | I235: Text drawn on top in code. | J235: res://art/endings/end_06_score_screen_board.png | K235: Beta | L235: Must | M235: F31 | N235: No | O235: 5 | P235: Not started
A236: MNU-01 | B236: Title and menus | C236: Title key art (layered) | D236: The game's key image: the knarr under sail at the edge of a new coast, a single figure at the bow, a vast sky. Painted in layers (sky, far coast, sea, ship, foreground spray) for slow parallax behind the menu. | E236: Title, Steam, itch | F236: Layered illustration | G236: 3840×2160 source, 1920×1080 in game | H236: 5 layers | I236: This one painting feeds most store art; paint it at 3840×2160. | J236: res://art/menus/mnu_01_title_key_art.png | K236: Beta | L236: Must | M236: F34 | N236: Yes | O236: 24 | P236: Not started
...
